<?xml version="1.0" ?>
<robot name="avatar" xmlns:controller="http://playerstage.sourceforge.net/gazebo/xmlschema/#controller" xmlns:interface="http://playerstage.sourceforge.net/gazebo/xmlschema/#interface" xmlns:sensor="http://playerstage.sourceforge.net/gazebo/xmlschema/#sensor">
  <!-- Avatar mounting shopstand, y forward, z up -->
  <link name="avatar_mount_shopstand">
    <visual>
      <origin rpy="0 0 0" xyz="0.4572 0.3048 -0.1"/>
      <geometry>
        <box size="0.9144 0.6096 0.2"/>
      </geometry>
    </visual>
  </link>
  <!-- World Connection -->
  <link name="world"/>
  <joint name="avatar_mount_shopstand" type="fixed">
    <parent link="world"/>
    <child link="avatar_mount_shopstand"/>
    <origin rpy="0.0 0.0 0.0" xyz="0.1 0.1 0.0"/>
  </joint>
  <!-- connect avatar mount shopstand to gofa 1 -->
  <joint name="gofa1_workspace" type="fixed">
    <parent link="avatar_mount_shopstand"/>
    <child link="gofa1_workspace"/>
    <origin rpy="0.0 0.0 0.0" xyz="0.1524 0.14605 0.0"/>
  </joint>
  <material name="Blue">
    <color rgba="0.0 0.0 0.8 1.0"/>
  </material>
  <material name="Green">
    <color rgba="0.0 0.8 0.0 1.0"/>
  </material>
  <material name="BiotacGreen">
    <color rgba="0.31 0.85 0.42 1.0"/>
  </material>
  <material name="Grey">
    <color rgba="0.2 0.2 0.2 1.0"/>
  </material>
  <material name="LightGrey">
    <color rgba="0.6 0.6 0.6 1.0"/>
  </material>
  <material name="Red">
    <color rgba="0.8 0.0 0.0 1.0"/>
  </material>
  <material name="White">
    <color rgba="1.0 1.0 1.0 1.0"/>
  </material>
  <gazebo>
    <plugin filename="libgazebo_ros_control.so" name="gazebo_ros_control">
      <robotSimType>sr_gazebo_sim/SrGazeboHWSim</robotSimType>
    </plugin>
  </gazebo>
  <!-- Conversion were obtained from http://www.e-paint.co.uk/Lab_values.asp
       unless otherwise stated. -->
  <!-- link list -->
  <link name="gofa1_base">
    <!-- See note 1 in package.xml about the inertial and mass values -->
    <inertial>
      <mass value="3.50083457958494"/>
      <origin xyz="-0.0012013793465437 -0.000175191786981708 0.0862146007385352"/>
      <inertia ixx="0.0153015257917955" ixy="-6.40155032892694E-05" ixz="-0.000276708687772683" iyy="0.0159333503953857" iyz="-3.98029144780725E-05" izz="0.0112162302268266"/>
    </inertial>
    <collision name="collision">
      <geometry>
        <mesh filename="avatar_model/abb_gofa/meshes/collision_stl/base.STL"/>
      </geometry>
    </collision>
    <visual name="visual">
      <geometry>
        <mesh filename="avatar_model/abb_gofa/meshes/visual_stl/base.STL"/>
      </geometry>
      <material name="">
        <color rgba="1 1 0 1"/>
      </material>
    </visual>
  </link>
  <link name="gofa1_link_1">
    <!-- See note 1 in package.xml about the inertial and mass values -->
    <inertial>
      <mass value="2.76743491139404"/>
      <origin xyz="2.08682453325091E-06 0.0103608399967513 0.0705307203199506"/>
      <inertia ixx="0.0115158625894577" ixy="6.37197693598838E-08" ixz="5.98954393680154E-09" iyy="0.006494848329231" iyz="-0.000196668400316843" izz="0.0109446835358581"/>
    </inertial>
    <collision name="collision">
      <geometry>
        <mesh filename="avatar_model/abb_gofa/meshes/collision_stl/link_1.STL"/>
      </geometry>
    </collision>
    <visual name="visual">
      <geometry>
        <mesh filename="avatar_model/abb_gofa/meshes/visual_stl/link_1.STL"/>
      </geometry>
      <material name="">
        <color rgba="1 1 0 1"/>
      </material>
    </visual>
  </link>
  <link name="gofa1_link_2">
    <!-- See note 1 in package.xml about the inertial and mass values -->
    <inertial>
      <mass value="4.2890416"/>
      <origin xyz="1.34018352211628E-06 -0.0500118376116071 0.222001399322246"/>
      <inertia ixx="0.130524729873898" ixy="1.31811857134115E-07" ixz="1.99022457670482E-06" iyy="0.133278449324229" iyz="-4.48622200366709E-07" izz="0.00669457974697178"/>
    </inertial>
    <collision name="collision">
      <geometry>
        <mesh filename="avatar_model/abb_gofa/meshes/collision_stl/link_2.STL"/>
      </geometry>
    </collision>
    <visual name="visual">
      <geometry>
        <mesh filename="avatar_model/abb_gofa/meshes/visual_stl/link_2.STL"/>
      </geometry>
      <material name="">
        <color rgba="1 1 0 1"/>
      </material>
    </visual>
  </link>
  <link name="gofa1_link_3">
    <!-- See note 1 in package.xml about the inertial and mass values -->
    <inertial>
      <mass value="3.38333107992875"/>
      <origin xyz="0.0128129281453599 0.0944171780907046 0.0247427540642403"/>
      <inertia ixx="0.0175626138728642" ixy="0.000364866179108744" ixz="-0.00318670290285352" iyy="0.0140230068919562" iyz="0.000704668055158407" izz="0.013275205067567"/>
    </inertial>
    <collision name="collision">
      <geometry>
        <mesh filename="avatar_model/abb_gofa/meshes/collision_stl/link_3.STL"/>
      </geometry>
    </collision>
    <visual name="visual">
      <geometry>
        <mesh filename="avatar_model/abb_gofa/meshes/visual_stl/link_3.STL"/>
      </geometry>
      <material name="">
        <color rgba="1 1 0 1"/>
      </material>
    </visual>
  </link>
  <link name="gofa1_link_4">
    <!-- See note 1 in package.xml about the inertial and mass values -->
    <inertial>
      <mass value="2.77857535641324"/>
      <origin xyz="0.160558561602322 0.041976811408979 -2.36623354021859E-07"/>
      <inertia ixx="0.00881683095901354" ixy="-0.010746260580237" ixz="1.2899930119841E-07" iyy="0.0340754175571832" iyz="3.96362791626429E-08" izz="0.0389358932156922"/>
    </inertial>
    <collision name="collision">
      <geometry>
        <mesh filename="avatar_model/abb_gofa/meshes/collision_stl/link_4.STL"/>
      </geometry>
    </collision>
    <visual name="visual">
      <geometry>
        <mesh filename="avatar_model/abb_gofa/meshes/visual_stl/link_4.STL"/>
      </geometry>
      <material name="">
        <color rgba="1 1 0 1"/>
      </material>
    </visual>
  </link>
  <link name="gofa1_link_5">
    <!-- See note 1 in package.xml about the inertial and mass values -->
    <inertial>
      <mass value="3.01105814739001"/>
      <origin xyz="-0.0147152361879962 -0.0785646469392633 0.0427558021601431"/>
      <inertia ixx="0.0114597336686444" ixy="0.000180094704361231" ixz="0.00165207280226761" iyy="0.013561904467501" iyz="-0.000525272443978826" izz="0.0108480119549914"/>
    </inertial>
    <collision name="collision">
      <geometry>
        <mesh filename="avatar_model/abb_gofa/meshes/collision_stl/link_5.STL"/>
      </geometry>
    </collision>
    <visual name="visual">
      <geometry>
        <mesh filename="avatar_model/abb_gofa/meshes/visual_stl/link_5.STL"/>
      </geometry>
      <material name="">
        <color rgba="1 1 0 1"/>
      </material>
    </visual>
  </link>
  <link name="gofa1_link_6">
    <!-- See note 1 in package.xml about the inertial and mass values -->
    <inertial>
      <mass value="0.146500988015653"/>
      <origin rpy="0 0 0" xyz="0.0137506852604966 0.000239804131398652 -0.000341962798940165"/>
      <inertia ixx="0.000128977630055306" ixy="-8.7622752508613E-08" ixz="1.18851551870012E-07" iyy="7.61118177829087E-05" iyz="-6.49821554399679E-07" izz="7.65022909768016E-05"/>
    </inertial>
    <!-- Meshlab calculated values (below) make gazebo crash when rotating this joint. -->
    <!-- <inertial>
        <mass value="0.00686711"/>
        <origin xyz="-0.00250976 -1.89e-06 0.00010218"/>
        <inertia ixx="1.3517e-06" ixy="-1.21316e-11" ixz="9.18065e-12" iyy="6.89813e-07" iyz="-1.21534e-10" izz="6.90097e-07"/>
      </inertial> -->
    <collision name="collision">
      <geometry>
        <mesh filename="avatar_model/abb_gofa/meshes/collision_stl/link_6.STL"/>
      </geometry>
    </collision>
    <visual name="visual">
      <geometry>
        <mesh filename="avatar_model/abb_gofa/meshes/visual_stl/link_6.STL"/>
      </geometry>
      <material name="">
        <color rgba="1 1 0 1"/>
      </material>
    </visual>
  </link>
  <!-- end of link list -->
  <!-- joint list -->
  <joint name="gofa1_joint_1" type="revolute">
    <origin rpy="0 0 0" xyz="0 0 0.1875"/>
    <axis xyz="0 0 1"/>
    <parent link="gofa1_base"/>
    <child link="gofa1_link_1"/>
    <!-- See note 2 in package.xml about effort limits and dynamics values -->
    <limit effort="1000" lower="-2.967" upper="2.967" velocity="5.027"/>
    <dynamics damping="50.0" friction="1.0"/>
  </joint>
  <joint name="gofa1_joint_2" type="revolute">
    <origin rpy="0 0 0" xyz="0 -0.085 0.0775"/>
    <axis xyz="0 1 0"/>
    <parent link="gofa1_link_1"/>
    <child link="gofa1_link_2"/>
    <!-- See note 2 in package.xml about effort limits and dynamics values -->
    <limit effort="1000" lower="-1.745" upper="2.269" velocity="4.189"/>
    <dynamics damping="50.0" friction="1.0"/>
  </joint>
  <joint name="gofa1_joint_3" type="revolute">
    <origin rpy="0 0 0" xyz="0 -0.00100000000000007 0.444"/>
    <axis xyz="0 1 0"/>
    <parent link="gofa1_link_2"/>
    <child link="gofa1_link_3"/>
    <!-- See note 2 in package.xml about effort limits and dynamics values -->
    <limit effort="1000" lower="-3.491" upper="1.222" velocity="5.236"/>
    <dynamics damping="10.0" friction="1.0"/>
  </joint>
  <joint name="gofa1_joint_4" type="revolute">
    <origin rpy="0 0 0" xyz="0.096 0.0860000000000001 0.11"/>
    <axis xyz="1 0 0"/>
    <parent link="gofa1_link_3"/>
    <child link="gofa1_link_4"/>
    <!-- See note 2 in package.xml about effort limits and dynamics values -->
    <limit effort="1000" lower="-4.712" upper="4.712" velocity="6.981"/>
    <dynamics damping="5.0" friction="1.0"/>
  </joint>
  <joint name="gofa1_joint_5" type="revolute">
    <origin rpy="0 0 0" xyz="0.374 0.0744999999999998 0"/>
    <axis xyz="0 1 0"/>
    <parent link="gofa1_link_4"/>
    <child link="gofa1_link_5"/>
    <!-- See note 2 in package.xml about effort limits and dynamics values -->
    <limit effort="1000" lower="-2.269" upper="2.269" velocity="7.069"/>
    <dynamics damping="2.0" friction="1.0"/>
  </joint>
  <joint name="gofa1_joint_6" type="revolute">
    <origin rpy="0 0 0" xyz="0.0679999999999995 -0.0744999999999998 0.0800000000000003"/>
    <axis xyz="1 0 0"/>
    <parent link="gofa1_link_5"/>
    <child link="gofa1_link_6"/>
    <!-- See note 2 in package.xml about effort limits and dynamics values -->
    <limit effort="1000" lower="-6.283" upper="6.283" velocity="10.472"/>
    <dynamics damping="1.0" friction="1.0"/>
  </joint>
  <!-- end of joint list -->
  <!-- ROS-Industrial 'base' frame- base_link to ABB World Coordinates transform -->
  <link name="gofa1_base_link"/>
  <joint name="gofa1_base_link-base" type="fixed">
    <origin rpy="0 0 0" xyz="0 0 0"/>
    <parent link="gofa1_base_link"/>
    <child link="gofa1_base"/>
  </joint>
  <!-- ROS-Industrial 'tool0' frame- all-zeros tool frame -->
  <link name="gofa1_tool0"/>
  <joint name="gofa1_link_6-tool0" type="fixed">
    <origin rpy="0 1.5708 0" xyz="0.0326 0 0"/>
    <parent link="gofa1_link_6"/>
    <child link="gofa1_tool0"/>
  </joint>
  <joint name="lh_world_joint" type="fixed">
    <parent link="gofa1_tool0"/>
    <child link="lh_forearm"/>
    <origin rpy="0.0 0.0 0.0" xyz="0.0 0.0 0.007"/>
  </joint>
  <link name="lh_forearm">
    <inertial>
      <origin rpy="0 0 0" xyz="0 0 0.09"/>
      <mass value="3.0"/>
      <inertia ixx="0.0138" ixy="0.0" ixz="0.0" iyy="0.0138" iyz="0.0" izz="0.00744"/>
    </inertial>
    <visual>
      <origin rpy="0 0 0" xyz="0 0 0.0"/>
      <geometry name="lh_forearm_visual">
        <mesh filename="avatar_model/shadow_hand/meshes/collision_stl/forearm.stl" scale="0.001 0.001 0.001"/>
      </geometry>
      <material name="light_grey">
        <color rgba="0.90000 0.90000 0.90000 1.0"/>
      </material>
    </visual>
    <collision>
      <origin rpy="0 0 0" xyz="0 0 0.0"/>
      <geometry name="lh_forearm_collision">
        <mesh filename="avatar_model/shadow_hand/meshes/collision_stl/forearm.stl" scale="0.001 0.001 0.001"/>
      </geometry>
    </collision>
    <!-- wrist mount -->
    <collision>
      <origin rpy="0 0.78 0" xyz="0 -0.01 0.181"/>
      <geometry>
        <box size="0.07 0.07 0.07"/>
      </geometry>
    </collision>
    <!-- TODO: Make a decision on whether to add the connector or not -->
    <!--visual>
        <origin rpy="0 -1.57 -1.57" xyz="0.0 0.067 0.0045"/>
        <geometry name="${prefix}cable_extr_visualisation">
          <mesh filename="avatar_model/shadow_hand/meshes/collision_obj/cable_connector/cable_connector_base_${hand_version}.dae" scale="0.001 0.001 0.001" />
        </geometry>
      </visual-->
  </link>
  <gazebo reference="lh_forearm">
    <selfCollide>false</selfCollide>
  </gazebo>
  <link name="lh_wrist">
    <inertial>
      <origin rpy="0 0 0" xyz="0 0 0.029"/>
      <mass value="0.1"/>
      <inertia ixx="0.000035" ixy="0.0" ixz="0.0" iyy="0.000064" iyz="0.0" izz="0.0000438"/>
    </inertial>
    <visual>
      <origin rpy="0 0 0" xyz="0 0 0"/>
      <geometry name="lh_wrist_visual">
        <mesh filename="avatar_model/shadow_hand/meshes/collision_stl/wrist.stl" scale="0.001 0.001 0.001"/>
      </geometry>
      <material name="LightGrey"/>
    </visual>
    <collision>
      <origin rpy="1.5708 1.5708 0" xyz="0 0 0"/>
      <geometry name="lh_wrist_collision_geom">
        <cylinder length="0.030" radius="0.0135"/>
      </geometry>
    </collision>
    <collision>
      <origin rpy="0 1.5708 0" xyz="0.026 0 0.034"/>
      <geometry>
        <cylinder length="0.010" radius="0.011"/>
      </geometry>
    </collision>
    <collision>
      <origin rpy="0 1.5708 0" xyz="-0.031 0 0.034"/>
      <geometry>
        <cylinder length="0.010" radius="0.011"/>
      </geometry>
    </collision>
    <collision>
      <origin rpy="0 -0.7854 0" xyz="0.021 0 0.011"/>
      <geometry>
        <box size="0.027 0.018 0.010"/>
      </geometry>
    </collision>
    <collision>
      <origin rpy="0 0.7854 0" xyz="-0.026 0 0.010"/>
      <geometry>
        <box size="0.027 0.018 0.010"/>
      </geometry>
    </collision>
  </link>
  <gazebo reference="lh_wrist">
    <material>Gazebo/White</material>
    <selfCollide>false</selfCollide>
  </gazebo>
  <joint name="lh_WRJ2" type="revolute">
    <parent link="lh_forearm"/>
    <child link="lh_wrist"/>
    <origin rpy="0 0 0" xyz="0 -0.010 0.21301"/>
    <axis xyz="0 -1 0"/>
    <limit effort="10" lower="-0.5235987755982988" upper="0.17453292519943295" velocity="2.0"/>
    <dynamics damping="0.1"/>
  </joint>
  <gazebo reference="lh_WRJ2">
    <provideFeedback>1</provideFeedback>
    <implicitSpringDamper>1</implicitSpringDamper>
  </gazebo>
  <transmission name="lh_wrist_transmission">
    <type>sr_mechanism_model/SimpleTransmission</type>
    <actuator name="lh_WRJ2">
      <mechanicalReduction>1</mechanicalReduction>
    </actuator>
    <joint name="lh_WRJ2">
      <hardwareInterface>EffortJointInterface</hardwareInterface>
      <hardwareInterface>PositionJointInterface</hardwareInterface>
    </joint>
  </transmission>
  <link name="lh_palm">
    <inertial>
      <origin rpy="0 0 0" xyz="0 0 0.035"/>
      <mass value="0.3"/>
      <inertia ixx="0.0003581" ixy="0.0" ixz="0.0" iyy="0.0005287" iyz="0.0" izz="0.000191"/>
    </inertial>
    <visual>
      <origin rpy="0 0 0" xyz="0 0 0"/>
      <geometry name="lh_palm_visual">
        <mesh filename="avatar_model/shadow_hand/meshes/collision_stl/palm.stl" scale="0.001 0.001 0.001"/>
      </geometry>
      <material name="Grey"/>
    </visual>
    <collision>
      <origin rpy="0 0 0" xyz="-0.011 0.0085 0.038"/>
      <geometry name="lh_palm_collision_geom">
        <box size="0.062 0.007 0.098"/>
      </geometry>
    </collision>
    <collision>
      <origin rpy="0 0 0" xyz="0.002 -0.0035 0.038"/>
      <geometry>
        <box size="0.036 0.017 0.098"/>
      </geometry>
    </collision>
    <!-- palm complement below first finger -->
    <collision>
      <origin rpy="0 0 0" xyz="-0.029 -0.0035 0.082"/>
      <geometry>
        <box size="0.026 0.017 0.010"/>
      </geometry>
    </collision>
    <collision>
      <origin rpy="0.2 0 -0.25" xyz="-0.0265 -0.001 0.070"/>
      <geometry>
        <box size="0.026 0.014 0.018"/>
      </geometry>
    </collision>
    <!-- thumb pulp side -->
    <collision>
      <origin rpy="0 0 0" xyz="-0.0315 -0.0085 0.001"/>
      <geometry>
        <box size="0.021 0.027 0.024"/>
      </geometry>
    </collision>
    <!-- thumb pulp central -->
    <collision>
      <origin rpy="0 0 0.48" xyz="-0.0125 -0.015 0.009"/>
      <geometry>
        <box size="0.022 0.005 0.040"/>
      </geometry>
    </collision>
    <!-- above middle finger-->
    <collision>
      <origin rpy="0 0 0" xyz="-0.011 0 0.089"/>
      <geometry>
        <box size="0.018 0.024 0.004"/>
      </geometry>
    </collision>
    <!-- metacarpal side-->
    <collision>
      <origin rpy="0 0 0" xyz="0.03 0 0.009"/>
      <geometry>
        <box size="0.020 0.024 0.040"/>
      </geometry>
    </collision>
  </link>
  <joint name="lh_ee_fixed_joint" type="fixed">
    <parent link="lh_palm"/>
    <child link="lh_manipulator"/>
    <origin rpy="0.0 0.0 0.0" xyz="0.0 0.0 0.05"/>
  </joint>
  <link name="lh_manipulator"/>
  <joint name="lh_WRJ1" type="revolute">
    <parent link="lh_wrist"/>
    <child link="lh_palm"/>
    <origin rpy="0 0 0" xyz="0 0 0.034"/>
    <axis xyz="1 0 0"/>
    <limit effort="30" lower="-0.6981317007977318" upper="0.4886921905584123" velocity="2.0"/>
    <dynamics damping="0.1"/>
  </joint>
  <gazebo reference="lh_WRJ1">
    <provideFeedback>1</provideFeedback>
    <implicitSpringDamper>1</implicitSpringDamper>
  </gazebo>
  <link name="lh_imu"/>
  <joint name="lh_palm_to_imu" type="fixed">
    <parent link="lh_palm"/>
    <child link="lh_imu"/>
    <origin rpy="-1.5707963 3.141592 0.0" xyz="0.01785 0.00765 0.049125"/>
  </joint>
  <transmission name="lh_palm_transmission">
    <type>sr_mechanism_model/SimpleTransmission</type>
    <actuator name="lh_WRJ1">
      <mechanicalReduction>1</mechanicalReduction>
    </actuator>
    <joint name="lh_WRJ1">
      <hardwareInterface>EffortJointInterface</hardwareInterface>
      <hardwareInterface>PositionJointInterface</hardwareInterface>
    </joint>
  </transmission>
  <gazebo reference="lh_palm">
  </gazebo>
  <link name="lh_ffknuckle">
    <inertial>
      <origin rpy="0 0 0" xyz="0 0 0"/>
      <mass value="0.008"/>
      <inertia ixx="0.00000026" ixy="0.0" ixz="0.0" iyy="0.00000026" iyz="0.0" izz="0.00000032"/>
    </inertial>
    <visual>
      <origin rpy="0 0 0" xyz="0 0 0.0005"/>
      <geometry name="lh_ffknuckle_visual">
        <mesh filename="avatar_model/shadow_hand/meshes/collision_stl/knuckle.stl" scale="0.001 0.001 0.001"/>
      </geometry>
      <material name="LightGrey"/>
    </visual>
    <collision>
      <origin rpy="0 1.5708 0" xyz="0 0 0"/>
      <geometry name="lh_ffknuckle_collision_geom">
        <cylinder length="0.014" radius="0.007"/>
      </geometry>
    </collision>
  </link>
  <joint name="lh_FFJ4" type="revolute">
    <parent link="lh_palm"/>
    <child link="lh_ffknuckle"/>
    <!--<origin xyz="0.033 0 0.095" rpy="0 0 0" />-->
    <origin rpy="0 0 0" xyz="-0.033 0 0.095"/>
    <axis xyz="0 1 0"/>
    <limit effort="2" lower="-0.3490658503988659" upper="0.3490658503988659" velocity="2.0"/>
    <dynamics damping="0.1"/>
  </joint>
  <gazebo reference="lh_FFJ4">
    <provideFeedback>1</provideFeedback>
    <implicitSpringDamper>1</implicitSpringDamper>
  </gazebo>
  <transmission name="lh_ffknuckle_transmission">
    <type>sr_mechanism_model/SimpleTransmission</type>
    <actuator name="lh_FFJ4">
      <mechanicalReduction>1</mechanicalReduction>
    </actuator>
    <joint name="lh_FFJ4">
      <hardwareInterface>EffortJointInterface</hardwareInterface>
      <hardwareInterface>PositionJointInterface</hardwareInterface>
    </joint>
  </transmission>
  <gazebo reference="lh_ffknuckle">
    <!-- knuckle is not highly exposed, so bumper is not useful -->
    <material>Gazebo/Grey</material>
  </gazebo>
  <link name="lh_ffproximal">
    <inertial>
      <mass value="0.030"/>
      <origin xyz="0 0 0.0225"/>
      <inertia ixx="0.0000098" ixy="0.0" ixz="0.0" iyy="0.00001" iyz="0.0" izz="0.0000018"/>
    </inertial>
    <visual>
      <origin rpy="0 0 0" xyz="0 0 0"/>
      <geometry name="lh_ffproximal_visual">
        <mesh filename="avatar_model/shadow_hand/meshes/collision_stl/finger_proximal.stl" scale="0.001 0.001 0.001"/>
      </geometry>
      <material name="Grey"/>
    </visual>
    <collision>
      <origin rpy="0 0 0" xyz="0 0 0.025"/>
      <geometry name="lh_ffproximal_collision_geom">
        <cylinder length="0.040" radius="0.007"/>
      </geometry>
    </collision>
  </link>
  <joint name="lh_FFJ3" type="revolute">
    <parent link="lh_ffknuckle"/>
    <child link="lh_ffproximal"/>
    <origin rpy="0 0 0" xyz="0 0 0"/>
    <axis xyz="1 0 0"/>
    <limit effort="2" lower="-0.2617993877991494" upper="1.5707963267948966" velocity="2.0"/>
    <dynamics damping="0.1"/>
  </joint>
  <gazebo reference="lh_FFJ3">
    <provideFeedback>1</provideFeedback>
    <implicitSpringDamper>1</implicitSpringDamper>
  </gazebo>
  <transmission name="lh_ffproximal_transmission">
    <type>sr_mechanism_model/SimpleTransmission</type>
    <actuator name="lh_FFJ3">
      <mechanicalReduction>1</mechanicalReduction>
    </actuator>
    <joint name="lh_FFJ3">
      <hardwareInterface>EffortJointInterface</hardwareInterface>
      <hardwareInterface>PositionJointInterface</hardwareInterface>
    </joint>
  </transmission>
  <gazebo reference="lh_ffproximal">
    <selfCollide>true</selfCollide>
  </gazebo>
  <link name="lh_ffmiddle">
    <inertial>
      <origin rpy="0 0 0" xyz="0 0 0.0125"/>
      <mass value="0.017"/>
      <inertia ixx="0.0000026" ixy="0.0" ixz="0.0" iyy="0.0000027" iyz="0.0" izz="0.00000087"/>
    </inertial>
    <visual>
      <origin rpy="0 0 0" xyz="0 0 0"/>
      <geometry name="lh_ffmiddle_visual">
        <mesh filename="avatar_model/shadow_hand/meshes/collision_stl/finger_middle.stl" scale="0.001 0.001 0.001"/>
      </geometry>
      <material name="Grey"/>
    </visual>
    <collision>
      <origin rpy="0 0 0" xyz="0 0 0.0125"/>
      <geometry name="lh_ffmiddle_collision_geom">
        <cylinder length="0.025" radius="0.007"/>
      </geometry>
    </collision>
    <collision>
      <origin rpy="0 0 0" xyz="0 0 0.0"/>
      <geometry>
        <sphere radius="0.007"/>
      </geometry>
    </collision>
    <collision>
      <origin rpy="0 0 0" xyz="0 0 0.025"/>
      <geometry>
        <sphere radius="0.007"/>
      </geometry>
    </collision>
  </link>
  <joint name="lh_FFJ2" type="revolute">
    <parent link="lh_ffproximal"/>
    <child link="lh_ffmiddle"/>
    <origin rpy="0 0 0" xyz="0 0 0.045"/>
    <axis xyz="1 0 0"/>
    <limit effort="2" lower="0" upper="1.5707963267948966" velocity="2.0"/>
    <dynamics damping="0.1"/>
  </joint>
  <gazebo reference="lh_FFJ2">
    <provideFeedback>1</provideFeedback>
    <implicitSpringDamper>1</implicitSpringDamper>
  </gazebo>
  <transmission name="lh_ffmiddle_transmission">
    <type>sr_mechanism_model/J0Transmission</type>
    <actuator name="lh_FFJ0">
      <mechanicalReduction>1</mechanicalReduction>
    </actuator>
    <joint name="lh_FFJ1">
      <hardwareInterface>EffortJointInterface</hardwareInterface>
      <hardwareInterface>PositionJointInterface</hardwareInterface>
    </joint>
  </transmission>
  <gazebo reference="lh_ffmiddle">
    <selfCollide>true</selfCollide>
  </gazebo>
  <link name="lh_ffdistal">
    <inertial>
      <mass value="0.012"/>
      <origin xyz="0 0 0.012"/>
      <inertia ixx="0.00000094" ixy="0.0" ixz="0.0" iyy="0.0000011" iyz="0.0" izz="0.00000053"/>
    </inertial>
    <visual>
      <origin rpy="0 0 0" xyz="0 0 0"/>
      <geometry name="lh_ffdistal_visual">
        <mesh filename="avatar_model/shadow_hand/meshes/collision_stl/finger_distal.stl" scale="0.001 0.001 0.001"/>
      </geometry>
    </visual>
    <collision>
      <origin rpy="0 0 0" xyz="0 0 0"/>
      <geometry name="lh_ffdistal_collision_geom">
        <mesh filename="avatar_model/shadow_hand/meshes/collision_stl/finger_distal.stl" scale="0.001 0.001 0.001"/>
      </geometry>
    </collision>
  </link>
  <joint name="lh_FFJ1" type="revolute">
    <parent link="lh_ffmiddle"/>
    <child link="lh_ffdistal"/>
    <origin rpy="0 0 0" xyz="0 0 0.025"/>
    <axis xyz="1 0 0"/>
    <!-- standard distal joint -->
    <limit effort="2" lower="0" upper="1.5707963267948966" velocity="2.0"/>
    <dynamics damping="0.1"/>
  </joint>
  <gazebo reference="lh_FFJ1">
    <provideFeedback>1</provideFeedback>
    <implicitSpringDamper>1</implicitSpringDamper>
  </gazebo>
  <link name="lh_fftip">
    <inertial>
      <mass value="0.001"/>
      <inertia ixx="0.0" ixy="0.0" ixz="0.0" iyy="0.0" iyz="0.0" izz="0.0"/>
    </inertial>
  </link>
  <joint name="lh_FFtip" type="fixed">
    <parent link="lh_ffdistal"/>
    <child link="lh_fftip"/>
    <origin rpy="0 0 0" xyz="0 0 0.026"/>
  </joint>
  <gazebo reference="lh_ffdistal">
    <sensor name="lh_ffdistal_contact" type="contact">
      <always_on>1</always_on>
      <update_rate>1000.0</update_rate>
      <contact>
        <collision>lh_ffdistal_collision</collision>
        <topic>lh_ffdistal_collision</topic>
      </contact>
      <plugin filename="libgazebo_ros_bumper.so" name="lh_ffdistal_gazebo_ros_bumper_controller">
        <alwaysOn>true</alwaysOn>
        <frameName>lh_ffdistal</frameName>
        <updateRate>100.0</updateRate>
        <bumperTopicName>contacts/lh_ff/distal</bumperTopicName>
      </plugin>
    </sensor>
    <mu1 value="500.0"/>
    <mu2 value="500.0"/>
    <kp value="10000000.0"/>
    <kd value="1.0"/>
    <selfCollide>true</selfCollide>
  </gazebo>
  <link name="lh_mfknuckle">
    <inertial>
      <origin rpy="0 0 0" xyz="0 0 0"/>
      <mass value="0.008"/>
      <inertia ixx="0.00000026" ixy="0.0" ixz="0.0" iyy="0.00000026" iyz="0.0" izz="0.00000032"/>
    </inertial>
    <visual>
      <origin rpy="0 0 0" xyz="0 0 0.0005"/>
      <geometry name="lh_mfknuckle_visual">
        <mesh filename="avatar_model/shadow_hand/meshes/collision_stl/knuckle.stl" scale="0.001 0.001 0.001"/>
      </geometry>
      <material name="LightGrey"/>
    </visual>
    <collision>
      <origin rpy="0 1.5708 0" xyz="0 0 0"/>
      <geometry name="lh_mfknuckle_collision_geom">
        <cylinder length="0.014" radius="0.007"/>
      </geometry>
    </collision>
  </link>
  <joint name="lh_MFJ4" type="revolute">
    <parent link="lh_palm"/>
    <child link="lh_mfknuckle"/>
    <!--<origin xyz="0.033 0 0.095" rpy="0 0 0" />-->
    <origin rpy="0 0 0" xyz="-0.011 0 0.099"/>
    <axis xyz="0 1 0"/>
    <limit effort="2" lower="-0.3490658503988659" upper="0.3490658503988659" velocity="2.0"/>
    <dynamics damping="0.1"/>
  </joint>
  <gazebo reference="lh_MFJ4">
    <provideFeedback>1</provideFeedback>
    <implicitSpringDamper>1</implicitSpringDamper>
  </gazebo>
  <transmission name="lh_mfknuckle_transmission">
    <type>sr_mechanism_model/SimpleTransmission</type>
    <actuator name="lh_MFJ4">
      <mechanicalReduction>1</mechanicalReduction>
    </actuator>
    <joint name="lh_MFJ4">
      <hardwareInterface>EffortJointInterface</hardwareInterface>
      <hardwareInterface>PositionJointInterface</hardwareInterface>
    </joint>
  </transmission>
  <gazebo reference="lh_mfknuckle">
    <!-- knuckle is not highly exposed, so bumper is not useful -->
    <material>Gazebo/Grey</material>
  </gazebo>
  <link name="lh_mfproximal">
    <inertial>
      <mass value="0.030"/>
      <origin xyz="0 0 0.0225"/>
      <inertia ixx="0.0000098" ixy="0.0" ixz="0.0" iyy="0.00001" iyz="0.0" izz="0.0000018"/>
    </inertial>
    <visual>
      <origin rpy="0 0 0" xyz="0 0 0"/>
      <geometry name="lh_mfproximal_visual">
        <mesh filename="avatar_model/shadow_hand/meshes/collision_stl/finger_proximal.stl" scale="0.001 0.001 0.001"/>
      </geometry>
      <material name="Grey"/>
    </visual>
    <collision>
      <origin rpy="0 0 0" xyz="0 0 0.025"/>
      <geometry name="lh_mfproximal_collision_geom">
        <cylinder length="0.040" radius="0.007"/>
      </geometry>
    </collision>
  </link>
  <joint name="lh_MFJ3" type="revolute">
    <parent link="lh_mfknuckle"/>
    <child link="lh_mfproximal"/>
    <origin rpy="0 0 0" xyz="0 0 0"/>
    <axis xyz="1 0 0"/>
    <limit effort="2" lower="-0.2617993877991494" upper="1.5707963267948966" velocity="2.0"/>
    <dynamics damping="0.1"/>
  </joint>
  <gazebo reference="lh_MFJ3">
    <provideFeedback>1</provideFeedback>
    <implicitSpringDamper>1</implicitSpringDamper>
  </gazebo>
  <transmission name="lh_mfproximal_transmission">
    <type>sr_mechanism_model/SimpleTransmission</type>
    <actuator name="lh_MFJ3">
      <mechanicalReduction>1</mechanicalReduction>
    </actuator>
    <joint name="lh_MFJ3">
      <hardwareInterface>EffortJointInterface</hardwareInterface>
      <hardwareInterface>PositionJointInterface</hardwareInterface>
    </joint>
  </transmission>
  <gazebo reference="lh_mfproximal">
    <selfCollide>true</selfCollide>
  </gazebo>
  <link name="lh_mfmiddle">
    <inertial>
      <origin rpy="0 0 0" xyz="0 0 0.0125"/>
      <mass value="0.017"/>
      <inertia ixx="0.0000026" ixy="0.0" ixz="0.0" iyy="0.0000027" iyz="0.0" izz="0.00000087"/>
    </inertial>
    <visual>
      <origin rpy="0 0 0" xyz="0 0 0"/>
      <geometry name="lh_mfmiddle_visual">
        <mesh filename="avatar_model/shadow_hand/meshes/collision_stl/finger_middle.stl" scale="0.001 0.001 0.001"/>
      </geometry>
      <material name="Grey"/>
    </visual>
    <collision>
      <origin rpy="0 0 0" xyz="0 0 0.0125"/>
      <geometry name="lh_mfmiddle_collision_geom">
        <cylinder length="0.025" radius="0.007"/>
      </geometry>
    </collision>
    <collision>
      <origin rpy="0 0 0" xyz="0 0 0.0"/>
      <geometry>
        <sphere radius="0.007"/>
      </geometry>
    </collision>
    <collision>
      <origin rpy="0 0 0" xyz="0 0 0.025"/>
      <geometry>
        <sphere radius="0.007"/>
      </geometry>
    </collision>
  </link>
  <joint name="lh_MFJ2" type="revolute">
    <parent link="lh_mfproximal"/>
    <child link="lh_mfmiddle"/>
    <origin rpy="0 0 0" xyz="0 0 0.045"/>
    <axis xyz="1 0 0"/>
    <limit effort="2" lower="0" upper="1.5707963267948966" velocity="2.0"/>
    <dynamics damping="0.1"/>
  </joint>
  <gazebo reference="lh_MFJ2">
    <provideFeedback>1</provideFeedback>
    <implicitSpringDamper>1</implicitSpringDamper>
  </gazebo>
  <transmission name="lh_mfmiddle_transmission">
    <type>sr_mechanism_model/J0Transmission</type>
    <actuator name="lh_MFJ0">
      <mechanicalReduction>1</mechanicalReduction>
    </actuator>
    <joint name="lh_MFJ1">
      <hardwareInterface>EffortJointInterface</hardwareInterface>
      <hardwareInterface>PositionJointInterface</hardwareInterface>
    </joint>
  </transmission>
  <gazebo reference="lh_mfmiddle">
    <selfCollide>true</selfCollide>
  </gazebo>
  <link name="lh_mfdistal">
    <inertial>
      <mass value="0.012"/>
      <origin xyz="0 0 0.012"/>
      <inertia ixx="0.00000094" ixy="0.0" ixz="0.0" iyy="0.0000011" iyz="0.0" izz="0.00000053"/>
    </inertial>
    <visual>
      <origin rpy="0 0 0" xyz="0 0 0"/>
      <geometry name="lh_mfdistal_visual">
        <mesh filename="avatar_model/shadow_hand/meshes/collision_stl/finger_distal.stl" scale="0.001 0.001 0.001"/>
      </geometry>
    </visual>
    <collision>
      <origin rpy="0 0 0" xyz="0 0 0"/>
      <geometry name="lh_mfdistal_collision_geom">
        <mesh filename="avatar_model/shadow_hand/meshes/collision_stl/finger_distal.stl" scale="0.001 0.001 0.001"/>
      </geometry>
    </collision>
  </link>
  <joint name="lh_MFJ1" type="revolute">
    <parent link="lh_mfmiddle"/>
    <child link="lh_mfdistal"/>
    <origin rpy="0 0 0" xyz="0 0 0.025"/>
    <axis xyz="1 0 0"/>
    <!-- standard distal joint -->
    <limit effort="2" lower="0" upper="1.5707963267948966" velocity="2.0"/>
    <dynamics damping="0.1"/>
  </joint>
  <gazebo reference="lh_MFJ1">
    <provideFeedback>1</provideFeedback>
    <implicitSpringDamper>1</implicitSpringDamper>
  </gazebo>
  <link name="lh_mftip">
    <inertial>
      <mass value="0.001"/>
      <inertia ixx="0.0" ixy="0.0" ixz="0.0" iyy="0.0" iyz="0.0" izz="0.0"/>
    </inertial>
  </link>
  <joint name="lh_MFtip" type="fixed">
    <parent link="lh_mfdistal"/>
    <child link="lh_mftip"/>
    <origin rpy="0 0 0" xyz="0 0 0.026"/>
  </joint>
  <gazebo reference="lh_mfdistal">
    <sensor name="lh_mfdistal_contact" type="contact">
      <always_on>1</always_on>
      <update_rate>1000.0</update_rate>
      <contact>
        <collision>lh_mfdistal_collision</collision>
        <topic>lh_mfdistal_collision</topic>
      </contact>
      <plugin filename="libgazebo_ros_bumper.so" name="lh_mfdistal_gazebo_ros_bumper_controller">
        <alwaysOn>true</alwaysOn>
        <frameName>lh_mfdistal</frameName>
        <updateRate>100.0</updateRate>
        <bumperTopicName>contacts/lh_mf/distal</bumperTopicName>
      </plugin>
    </sensor>
    <mu1 value="500.0"/>
    <mu2 value="500.0"/>
    <kp value="10000000.0"/>
    <kd value="1.0"/>
    <selfCollide>true</selfCollide>
  </gazebo>
  <link name="lh_rfknuckle">
    <inertial>
      <origin rpy="0 0 0" xyz="0 0 0"/>
      <mass value="0.008"/>
      <inertia ixx="0.00000026" ixy="0.0" ixz="0.0" iyy="0.00000026" iyz="0.0" izz="0.00000032"/>
    </inertial>
    <visual>
      <origin rpy="0 0 0" xyz="0 0 0.0005"/>
      <geometry name="lh_rfknuckle_visual">
        <mesh filename="avatar_model/shadow_hand/meshes/collision_stl/knuckle.stl" scale="0.001 0.001 0.001"/>
      </geometry>
      <material name="LightGrey"/>
    </visual>
    <collision>
      <origin rpy="0 1.5708 0" xyz="0 0 0"/>
      <geometry name="lh_rfknuckle_collision_geom">
        <cylinder length="0.014" radius="0.007"/>
      </geometry>
    </collision>
  </link>
  <joint name="lh_RFJ4" type="revolute">
    <parent link="lh_palm"/>
    <child link="lh_rfknuckle"/>
    <!--<origin xyz="0.033 0 0.095" rpy="0 0 0" />-->
    <origin rpy="0 0 0" xyz="0.011 0 0.095"/>
    <axis xyz="0 -1 0"/>
    <limit effort="2" lower="-0.3490658503988659" upper="0.3490658503988659" velocity="2.0"/>
    <dynamics damping="0.1"/>
  </joint>
  <gazebo reference="lh_RFJ4">
    <provideFeedback>1</provideFeedback>
    <implicitSpringDamper>1</implicitSpringDamper>
  </gazebo>
  <transmission name="lh_rfknuckle_transmission">
    <type>sr_mechanism_model/SimpleTransmission</type>
    <actuator name="lh_RFJ4">
      <mechanicalReduction>1</mechanicalReduction>
    </actuator>
    <joint name="lh_RFJ4">
      <hardwareInterface>EffortJointInterface</hardwareInterface>
      <hardwareInterface>PositionJointInterface</hardwareInterface>
    </joint>
  </transmission>
  <gazebo reference="lh_rfknuckle">
    <!-- knuckle is not highly exposed, so bumper is not useful -->
    <material>Gazebo/Grey</material>
  </gazebo>
  <link name="lh_rfproximal">
    <inertial>
      <mass value="0.030"/>
      <origin xyz="0 0 0.0225"/>
      <inertia ixx="0.0000098" ixy="0.0" ixz="0.0" iyy="0.00001" iyz="0.0" izz="0.0000018"/>
    </inertial>
    <visual>
      <origin rpy="0 0 0" xyz="0 0 0"/>
      <geometry name="lh_rfproximal_visual">
        <mesh filename="avatar_model/shadow_hand/meshes/collision_stl/finger_proximal.stl" scale="0.001 0.001 0.001"/>
      </geometry>
      <material name="Grey"/>
    </visual>
    <collision>
      <origin rpy="0 0 0" xyz="0 0 0.025"/>
      <geometry name="lh_rfproximal_collision_geom">
        <cylinder length="0.040" radius="0.007"/>
      </geometry>
    </collision>
  </link>
  <joint name="lh_RFJ3" type="revolute">
    <parent link="lh_rfknuckle"/>
    <child link="lh_rfproximal"/>
    <origin rpy="0 0 0" xyz="0 0 0"/>
    <axis xyz="1 0 0"/>
    <limit effort="2" lower="-0.2617993877991494" upper="1.5707963267948966" velocity="2.0"/>
    <dynamics damping="0.1"/>
  </joint>
  <gazebo reference="lh_RFJ3">
    <provideFeedback>1</provideFeedback>
    <implicitSpringDamper>1</implicitSpringDamper>
  </gazebo>
  <transmission name="lh_rfproximal_transmission">
    <type>sr_mechanism_model/SimpleTransmission</type>
    <actuator name="lh_RFJ3">
      <mechanicalReduction>1</mechanicalReduction>
    </actuator>
    <joint name="lh_RFJ3">
      <hardwareInterface>EffortJointInterface</hardwareInterface>
      <hardwareInterface>PositionJointInterface</hardwareInterface>
    </joint>
  </transmission>
  <gazebo reference="lh_rfproximal">
    <selfCollide>true</selfCollide>
  </gazebo>
  <link name="lh_rfmiddle">
    <inertial>
      <origin rpy="0 0 0" xyz="0 0 0.0125"/>
      <mass value="0.017"/>
      <inertia ixx="0.0000026" ixy="0.0" ixz="0.0" iyy="0.0000027" iyz="0.0" izz="0.00000087"/>
    </inertial>
    <visual>
      <origin rpy="0 0 0" xyz="0 0 0"/>
      <geometry name="lh_rfmiddle_visual">
        <mesh filename="avatar_model/shadow_hand/meshes/collision_stl/finger_middle.stl" scale="0.001 0.001 0.001"/>
      </geometry>
      <material name="Grey"/>
    </visual>
    <collision>
      <origin rpy="0 0 0" xyz="0 0 0.0125"/>
      <geometry name="lh_rfmiddle_collision_geom">
        <cylinder length="0.025" radius="0.007"/>
      </geometry>
    </collision>
    <collision>
      <origin rpy="0 0 0" xyz="0 0 0.0"/>
      <geometry>
        <sphere radius="0.007"/>
      </geometry>
    </collision>
    <collision>
      <origin rpy="0 0 0" xyz="0 0 0.025"/>
      <geometry>
        <sphere radius="0.007"/>
      </geometry>
    </collision>
  </link>
  <joint name="lh_RFJ2" type="revolute">
    <parent link="lh_rfproximal"/>
    <child link="lh_rfmiddle"/>
    <origin rpy="0 0 0" xyz="0 0 0.045"/>
    <axis xyz="1 0 0"/>
    <limit effort="2" lower="0" upper="1.5707963267948966" velocity="2.0"/>
    <dynamics damping="0.1"/>
  </joint>
  <gazebo reference="lh_RFJ2">
    <provideFeedback>1</provideFeedback>
    <implicitSpringDamper>1</implicitSpringDamper>
  </gazebo>
  <transmission name="lh_rfmiddle_transmission">
    <type>sr_mechanism_model/J0Transmission</type>
    <actuator name="lh_RFJ0">
      <mechanicalReduction>1</mechanicalReduction>
    </actuator>
    <joint name="lh_RFJ1">
      <hardwareInterface>EffortJointInterface</hardwareInterface>
      <hardwareInterface>PositionJointInterface</hardwareInterface>
    </joint>
  </transmission>
  <gazebo reference="lh_rfmiddle">
    <selfCollide>true</selfCollide>
  </gazebo>
  <link name="lh_rfdistal">
    <inertial>
      <mass value="0.012"/>
      <origin xyz="0 0 0.012"/>
      <inertia ixx="0.00000094" ixy="0.0" ixz="0.0" iyy="0.0000011" iyz="0.0" izz="0.00000053"/>
    </inertial>
    <visual>
      <origin rpy="0 0 0" xyz="0 0 0"/>
      <geometry name="lh_rfdistal_visual">
        <mesh filename="avatar_model/shadow_hand/meshes/collision_stl/finger_distal.stl" scale="0.001 0.001 0.001"/>
      </geometry>
    </visual>
    <collision>
      <origin rpy="0 0 0" xyz="0 0 0"/>
      <geometry name="lh_rfdistal_collision_geom">
        <mesh filename="avatar_model/shadow_hand/meshes/collision_stl/finger_distal.stl" scale="0.001 0.001 0.001"/>
      </geometry>
    </collision>
  </link>
  <joint name="lh_RFJ1" type="revolute">
    <parent link="lh_rfmiddle"/>
    <child link="lh_rfdistal"/>
    <origin rpy="0 0 0" xyz="0 0 0.025"/>
    <axis xyz="1 0 0"/>
    <!-- standard distal joint -->
    <limit effort="2" lower="0" upper="1.5707963267948966" velocity="2.0"/>
    <dynamics damping="0.1"/>
  </joint>
  <gazebo reference="lh_RFJ1">
    <provideFeedback>1</provideFeedback>
    <implicitSpringDamper>1</implicitSpringDamper>
  </gazebo>
  <link name="lh_rftip">
    <inertial>
      <mass value="0.001"/>
      <inertia ixx="0.0" ixy="0.0" ixz="0.0" iyy="0.0" iyz="0.0" izz="0.0"/>
    </inertial>
  </link>
  <joint name="lh_RFtip" type="fixed">
    <parent link="lh_rfdistal"/>
    <child link="lh_rftip"/>
    <origin rpy="0 0 0" xyz="0 0 0.026"/>
  </joint>
  <gazebo reference="lh_rfdistal">
    <sensor name="lh_rfdistal_contact" type="contact">
      <always_on>1</always_on>
      <update_rate>1000.0</update_rate>
      <contact>
        <collision>lh_rfdistal_collision</collision>
        <topic>lh_rfdistal_collision</topic>
      </contact>
      <plugin filename="libgazebo_ros_bumper.so" name="lh_rfdistal_gazebo_ros_bumper_controller">
        <alwaysOn>true</alwaysOn>
        <frameName>lh_rfdistal</frameName>
        <updateRate>100.0</updateRate>
        <bumperTopicName>contacts/lh_rf/distal</bumperTopicName>
      </plugin>
    </sensor>
    <mu1 value="500.0"/>
    <mu2 value="500.0"/>
    <kp value="10000000.0"/>
    <kd value="1.0"/>
    <selfCollide>true</selfCollide>
  </gazebo>
  <link name="lh_lfmetacarpal">
    <inertial>
      <origin rpy="0 -0.9599 0" xyz="-0.03174867647058824 0 0.02235294117647059"/>
      <mass value="0.030"/>
      <inertia ixx="0.0000145" ixy="0.0" ixz="0.0" iyy="0.00001638" iyz="0.0" izz="0.000004272"/>
    </inertial>
    <visual>
      <origin rpy="0 -0.9599 0" xyz="0 0 0"/>
      <geometry name="lh_lfmetacarpal_visual">
        <mesh filename="avatar_model/shadow_hand/meshes/collision_stl/metacarpal.stl" scale="0.001 0.001 0.001"/>
      </geometry>
      <material name="Grey"/>
    </visual>
    <collision>
      <origin rpy="0 -0.9599 0" xyz="-0.026986375 0 0.019"/>
      <geometry name="lh_lfmetacarpal_collision_geom">
        <box size="0.018 0.024 0.040"/>
      </geometry>
    </collision>
  </link>
  <joint name="lh_LFJ5" type="revolute">
    <parent link="lh_palm"/>
    <child link="lh_lfmetacarpal"/>
    <origin rpy="0 0.9599 0" xyz="0.033 0 0.02071"/>
    <axis xyz="1 0 0"/>
    <limit effort="2" lower="0" upper="0.7853981633974483" velocity="2.0"/>
    <dynamics damping="0.1"/>
  </joint>
  <gazebo reference="lh_LFJ5">
    <provideFeedback>1</provideFeedback>
    <implicitSpringDamper>1</implicitSpringDamper>
  </gazebo>
  <transmission name="lh_lfmetacarpal_transmission">
    <type>sr_mechanism_model/SimpleTransmission</type>
    <actuator name="lh_LFJ5">
      <mechanicalReduction>1</mechanicalReduction>
    </actuator>
    <joint name="lh_LFJ5">
      <hardwareInterface>EffortJointInterface</hardwareInterface>
      <hardwareInterface>PositionJointInterface</hardwareInterface>
    </joint>
  </transmission>
  <gazebo reference="lh_lfmetacarpal">
    <selfCollide>true</selfCollide>
  </gazebo>
  <link name="lh_lfknuckle">
    <inertial>
      <origin rpy="0 0 0" xyz="0 0 0"/>
      <mass value="0.008"/>
      <inertia ixx="0.00000026" ixy="0.0" ixz="0.0" iyy="0.00000026" iyz="0.0" izz="0.00000032"/>
    </inertial>
    <visual>
      <origin rpy="0 0 0" xyz="0 0 0.0005"/>
      <geometry name="lh_lfknuckle_visual">
        <mesh filename="avatar_model/shadow_hand/meshes/collision_stl/knuckle.stl" scale="0.001 0.001 0.001"/>
      </geometry>
      <material name="LightGrey"/>
    </visual>
    <collision>
      <origin rpy="0 1.5708 0" xyz="0 0 0"/>
      <geometry name="lh_lfknuckle_collision_geom">
        <cylinder length="0.014" radius="0.007"/>
      </geometry>
    </collision>
  </link>
  <joint name="lh_LFJ4" type="revolute">
    <parent link="lh_lfmetacarpal"/>
    <child link="lh_lfknuckle"/>
    <!--<origin xyz="0.033 0 0.095" rpy="0 0 0" />-->
    <origin rpy="0 -0.9599 0" xyz="-0.05397275 0 0.03779463"/>
    <axis xyz="0 -1 0"/>
    <limit effort="2" lower="-0.3490658503988659" upper="0.3490658503988659" velocity="2.0"/>
    <dynamics damping="0.1"/>
  </joint>
  <gazebo reference="lh_LFJ4">
    <provideFeedback>1</provideFeedback>
    <implicitSpringDamper>1</implicitSpringDamper>
  </gazebo>
  <transmission name="lh_lfknuckle_transmission">
    <type>sr_mechanism_model/SimpleTransmission</type>
    <actuator name="lh_LFJ4">
      <mechanicalReduction>1</mechanicalReduction>
    </actuator>
    <joint name="lh_LFJ4">
      <hardwareInterface>EffortJointInterface</hardwareInterface>
      <hardwareInterface>PositionJointInterface</hardwareInterface>
    </joint>
  </transmission>
  <gazebo reference="lh_lfknuckle">
    <!-- knuckle is not highly exposed, so bumper is not useful -->
    <material>Gazebo/Grey</material>
  </gazebo>
  <link name="lh_lfproximal">
    <inertial>
      <mass value="0.030"/>
      <origin xyz="0 0 0.0225"/>
      <inertia ixx="0.0000098" ixy="0.0" ixz="0.0" iyy="0.00001" iyz="0.0" izz="0.0000018"/>
    </inertial>
    <visual>
      <origin rpy="0 0 0" xyz="0 0 0"/>
      <geometry name="lh_lfproximal_visual">
        <mesh filename="avatar_model/shadow_hand/meshes/collision_stl/finger_proximal.stl" scale="0.001 0.001 0.001"/>
      </geometry>
      <material name="Grey"/>
    </visual>
    <collision>
      <origin rpy="0 0 0" xyz="0 0 0.025"/>
      <geometry name="lh_lfproximal_collision_geom">
        <cylinder length="0.040" radius="0.007"/>
      </geometry>
    </collision>
  </link>
  <joint name="lh_LFJ3" type="revolute">
    <parent link="lh_lfknuckle"/>
    <child link="lh_lfproximal"/>
    <origin rpy="0 0 0" xyz="0 0 0"/>
    <axis xyz="1 0 0"/>
    <limit effort="2" lower="-0.2617993877991494" upper="1.5707963267948966" velocity="2.0"/>
    <dynamics damping="0.1"/>
  </joint>
  <gazebo reference="lh_LFJ3">
    <provideFeedback>1</provideFeedback>
    <implicitSpringDamper>1</implicitSpringDamper>
  </gazebo>
  <transmission name="lh_lfproximal_transmission">
    <type>sr_mechanism_model/SimpleTransmission</type>
    <actuator name="lh_LFJ3">
      <mechanicalReduction>1</mechanicalReduction>
    </actuator>
    <joint name="lh_LFJ3">
      <hardwareInterface>EffortJointInterface</hardwareInterface>
      <hardwareInterface>PositionJointInterface</hardwareInterface>
    </joint>
  </transmission>
  <gazebo reference="lh_lfproximal">
    <selfCollide>true</selfCollide>
  </gazebo>
  <link name="lh_lfmiddle">
    <inertial>
      <origin rpy="0 0 0" xyz="0 0 0.0125"/>
      <mass value="0.017"/>
      <inertia ixx="0.0000026" ixy="0.0" ixz="0.0" iyy="0.0000027" iyz="0.0" izz="0.00000087"/>
    </inertial>
    <visual>
      <origin rpy="0 0 0" xyz="0 0 0"/>
      <geometry name="lh_lfmiddle_visual">
        <mesh filename="avatar_model/shadow_hand/meshes/collision_stl/finger_middle.stl" scale="0.001 0.001 0.001"/>
      </geometry>
      <material name="Grey"/>
    </visual>
    <collision>
      <origin rpy="0 0 0" xyz="0 0 0.0125"/>
      <geometry name="lh_lfmiddle_collision_geom">
        <cylinder length="0.025" radius="0.007"/>
      </geometry>
    </collision>
    <collision>
      <origin rpy="0 0 0" xyz="0 0 0.0"/>
      <geometry>
        <sphere radius="0.007"/>
      </geometry>
    </collision>
    <collision>
      <origin rpy="0 0 0" xyz="0 0 0.025"/>
      <geometry>
        <sphere radius="0.007"/>
      </geometry>
    </collision>
  </link>
  <joint name="lh_LFJ2" type="revolute">
    <parent link="lh_lfproximal"/>
    <child link="lh_lfmiddle"/>
    <origin rpy="0 0 0" xyz="0 0 0.045"/>
    <axis xyz="1 0 0"/>
    <limit effort="2" lower="0" upper="1.5707963267948966" velocity="2.0"/>
    <dynamics damping="0.1"/>
  </joint>
  <gazebo reference="lh_LFJ2">
    <provideFeedback>1</provideFeedback>
    <implicitSpringDamper>1</implicitSpringDamper>
  </gazebo>
  <transmission name="lh_lfmiddle_transmission">
    <type>sr_mechanism_model/J0Transmission</type>
    <actuator name="lh_LFJ0">
      <mechanicalReduction>1</mechanicalReduction>
    </actuator>
    <joint name="lh_LFJ1">
      <hardwareInterface>EffortJointInterface</hardwareInterface>
      <hardwareInterface>PositionJointInterface</hardwareInterface>
    </joint>
  </transmission>
  <gazebo reference="lh_lfmiddle">
    <selfCollide>true</selfCollide>
  </gazebo>
  <link name="lh_lfdistal">
    <inertial>
      <mass value="0.012"/>
      <origin xyz="0 0 0.012"/>
      <inertia ixx="0.00000094" ixy="0.0" ixz="0.0" iyy="0.0000011" iyz="0.0" izz="0.00000053"/>
    </inertial>
    <visual>
      <origin rpy="0 0 0" xyz="0 0 0"/>
      <geometry name="lh_lfdistal_visual">
        <mesh filename="avatar_model/shadow_hand/meshes/collision_stl/finger_distal.stl" scale="0.001 0.001 0.001"/>
      </geometry>
    </visual>
    <collision>
      <origin rpy="0 0 0" xyz="0 0 0"/>
      <geometry name="lh_lfdistal_collision_geom">
        <mesh filename="avatar_model/shadow_hand/meshes/collision_stl/finger_distal.stl" scale="0.001 0.001 0.001"/>
      </geometry>
    </collision>
  </link>
  <joint name="lh_LFJ1" type="revolute">
    <parent link="lh_lfmiddle"/>
    <child link="lh_lfdistal"/>
    <origin rpy="0 0 0" xyz="0 0 0.025"/>
    <axis xyz="1 0 0"/>
    <!-- standard distal joint -->
    <limit effort="2" lower="0" upper="1.5707963267948966" velocity="2.0"/>
    <dynamics damping="0.1"/>
  </joint>
  <gazebo reference="lh_LFJ1">
    <provideFeedback>1</provideFeedback>
    <implicitSpringDamper>1</implicitSpringDamper>
  </gazebo>
  <link name="lh_lftip">
    <inertial>
      <mass value="0.001"/>
      <inertia ixx="0.0" ixy="0.0" ixz="0.0" iyy="0.0" iyz="0.0" izz="0.0"/>
    </inertial>
  </link>
  <joint name="lh_LFtip" type="fixed">
    <parent link="lh_lfdistal"/>
    <child link="lh_lftip"/>
    <origin rpy="0 0 0" xyz="0 0 0.026"/>
  </joint>
  <gazebo reference="lh_lfdistal">
    <sensor name="lh_lfdistal_contact" type="contact">
      <always_on>1</always_on>
      <update_rate>1000.0</update_rate>
      <contact>
        <collision>lh_lfdistal_collision</collision>
        <topic>lh_lfdistal_collision</topic>
      </contact>
      <plugin filename="libgazebo_ros_bumper.so" name="lh_lfdistal_gazebo_ros_bumper_controller">
        <alwaysOn>true</alwaysOn>
        <frameName>lh_lfdistal</frameName>
        <updateRate>100.0</updateRate>
        <bumperTopicName>contacts/lh_lf/distal</bumperTopicName>
      </plugin>
    </sensor>
    <mu1 value="500.0"/>
    <mu2 value="500.0"/>
    <kp value="10000000.0"/>
    <kd value="1.0"/>
    <selfCollide>true</selfCollide>
  </gazebo>
  <link name="lh_thbase">
    <inertial>
      <mass value="0.010"/>
      <origin rpy="0 0 0" xyz="0 0 0"/>
      <inertia ixx="0.00000016" ixy="0.0" ixz="0.0" iyy="0.00000016" iyz="0.0" izz="0.00000016"/>
    </inertial>
    <visual>
      <origin rpy="0 0 0" xyz="0 0 0"/>
      <geometry name="lh_thbase_visual">
        <box size="0.001 0.001 0.001"/>
      </geometry>
      <material name="shadow_thbase_material">
        <color rgba="0.5 0.5 0.5 1.0"/>
      </material>
    </visual>
    <collision>
      <origin rpy="0 0 0" xyz="0 0 0"/>
      <geometry name="lh_thbase_collision_geom">
        <sphere radius="0.011"/>
      </geometry>
    </collision>
  </link>
  <joint name="lh_THJ5" type="revolute">
    <parent link="lh_palm"/>
    <child link="lh_thbase"/>
    <origin rpy="-0.7853981633974483 0 1.5707963267948966" xyz="-0.034 -0.00858 0.029"/>
    <axis xyz="0 0 1"/>
    <limit effort="5.0" lower="-1.0471975511965976" upper="1.0471975511965976" velocity="4.0"/>
    <dynamics damping="0.2"/>
  </joint>
  <gazebo reference="lh_THJ5">
    <provideFeedback>1</provideFeedback>
    <implicitSpringDamper>1</implicitSpringDamper>
  </gazebo>
  <transmission name="lh_thbase_transmission">
    <type>sr_mechanism_model/SimpleTransmission</type>
    <actuator name="lh_THJ5">
      <mechanicalReduction>1</mechanicalReduction>
    </actuator>
    <joint name="lh_THJ5">
      <hardwareInterface>EffortJointInterface</hardwareInterface>
      <hardwareInterface>PositionJointInterface</hardwareInterface>
    </joint>
  </transmission>
  <gazebo reference="lh_thbase">
    <!-- base is inside the proximal and not exposed, so bumper is not needed -->
    <selfCollide>false</selfCollide>
  </gazebo>
  <link name="lh_thproximal">
    <inertial>
      <mass value="0.040"/>
      <origin rpy="0 0 0" xyz="0 0 0.019"/>
      <inertia ixx="0.0000136" ixy="0.0" ixz="0.0" iyy="0.0000136" iyz="0.0" izz="0.00000313"/>
    </inertial>
    <visual>
      <origin rpy="0 0 1.5707963267948966" xyz="0 0 0"/>
      <geometry name="lh_thproximal_visual">
        <mesh filename="avatar_model/shadow_hand/meshes/collision_stl/thumb_proximal.stl" scale="0.001 0.001 0.001"/>
      </geometry>
      <material name="shadow_thproximal_material">
        <color rgba="0.2 0.2 0.2 1.0"/>
      </material>
    </visual>
    <collision>
      <origin rpy="0 0 0" xyz="0 0 0.020"/>
      <geometry name="lh_thproximal_collision_geom">
        <cylinder length="0.018" radius="0.012"/>
      </geometry>
    </collision>
  </link>
  <joint name="lh_THJ4" type="revolute">
    <parent link="lh_thbase"/>
    <child link="lh_thproximal"/>
    <origin rpy="0 0 0" xyz="0 0 0"/>
    <axis xyz="0 -1 0"/>
    <limit effort="3" lower="0.0" upper="1.2217304763960306" velocity="4.0"/>
    <dynamics damping="0.2"/>
  </joint>
  <gazebo reference="lh_THJ4">
    <provideFeedback>1</provideFeedback>
    <implicitSpringDamper>1</implicitSpringDamper>
  </gazebo>
  <transmission name="lh_thproximal_transmission">
    <type>sr_mechanism_model/SimpleTransmission</type>
    <actuator name="lh_THJ4">
      <mechanicalReduction>1</mechanicalReduction>
    </actuator>
    <joint name="lh_THJ4">
      <hardwareInterface>EffortJointInterface</hardwareInterface>
      <hardwareInterface>PositionJointInterface</hardwareInterface>
    </joint>
  </transmission>
  <gazebo reference="lh_thproximal">
    <selfCollide>false</selfCollide>
  </gazebo>
  <link name="lh_thhub">
    <inertial>
      <mass value="0.005"/>
      <origin rpy="0 0 0" xyz="0 0 0"/>
      <inertia ixx="0.000001" ixy="0.0" ixz="0.0" iyy="0.000001" iyz="0.0" izz="0.0000003"/>
    </inertial>
    <visual>
      <origin rpy="0 0 0" xyz="0 0 0"/>
      <geometry name="lh_thhub_visual">
        <box size="0.001 0.001 0.001"/>
      </geometry>
      <material name="shadow_thhub_material">
        <color rgba="0.7 0.7 0.7 1.0"/>
      </material>
    </visual>
    <collision>
      <origin rpy="0 0 0" xyz="0 0 0"/>
      <geometry name="lh_thhub_collision_geom">
        <sphere radius="0.010"/>
      </geometry>
    </collision>
  </link>
  <joint name="lh_THJ3" type="revolute">
    <parent link="lh_thproximal"/>
    <child link="lh_thhub"/>
    <origin rpy="0 0 0" xyz="0 0 0.038"/>
    <axis xyz="0 -1 0"/>
    <limit effort="2.0" lower="-0.20943951023931953" upper="0.20943951023931953" velocity="4.0"/>
    <dynamics damping="0.2"/>
  </joint>
  <gazebo reference="lh_THJ3">
    <provideFeedback>1</provideFeedback>
    <implicitSpringDamper>1</implicitSpringDamper>
  </gazebo>
  <transmission name="lh_thhub_transmission">
    <type>sr_mechanism_model/SimpleTransmission</type>
    <actuator name="lh_THJ3">
      <mechanicalReduction>1</mechanicalReduction>
    </actuator>
    <joint name="lh_THJ3">
      <hardwareInterface>EffortJointInterface</hardwareInterface>
      <hardwareInterface>PositionJointInterface</hardwareInterface>
    </joint>
  </transmission>
  <gazebo reference="lh_thhub">
    <!-- hub is inside the proximal and not exposed, so bumper is not needed -->
    <selfCollide>false</selfCollide>
  </gazebo>
  <link name="lh_thmiddle">
    <inertial>
      <mass value="0.020"/>
      <origin rpy="0 0 0" xyz="0 0 0.016"/>
      <inertia ixx="0.0000051" ixy="0.0" ixz="0.0" iyy="0.0000051" iyz="0.0" izz="0.00000121"/>
    </inertial>
    <visual>
      <origin rpy="0 0 1.5707963267948966" xyz="0 0 0"/>
      <geometry name="lh_thmiddle_visual">
        <mesh filename="avatar_model/shadow_hand/meshes/collision_stl/thumb_middle.stl" scale="0.001 0.001 0.001"/>
      </geometry>
      <material name="shadow_thmiddle_material">
        <color rgba="0.2 0.2 0.2 1.0"/>
      </material>
    </visual>
    <collision>
      <origin rpy="0 0 0" xyz="0 0 0.012"/>
      <geometry name="lh_thmiddle_collision_geom">
        <cylinder length="0.018" radius="0.011"/>
      </geometry>
    </collision>
    <collision>
      <origin rpy="0 0 0" xyz="0 0 0.019"/>
      <geometry>
        <sphere radius="0.011"/>
      </geometry>
    </collision>
    <collision>
      <origin rpy="0 1.5708 0" xyz="0 0 0.032"/>
      <geometry>
        <cylinder length="0.014" radius="0.010"/>
      </geometry>
    </collision>
  </link>
  <joint name="lh_THJ2" type="revolute">
    <parent link="lh_thhub"/>
    <child link="lh_thmiddle"/>
    <origin rpy="0 0 0" xyz="0 0 0"/>
    <axis xyz="1 0 0"/>
    <limit effort="2.0" lower="-0.6981317007977318" upper="0.6981317007977318" velocity="2.0"/>
    <dynamics damping="0.1"/>
  </joint>
  <gazebo reference="lh_THJ2">
    <provideFeedback>1</provideFeedback>
    <implicitSpringDamper>1</implicitSpringDamper>
  </gazebo>
  <transmission name="lh_thmiddle_transmission">
    <type>sr_mechanism_model/SimpleTransmission</type>
    <actuator name="lh_THJ2">
      <mechanicalReduction>1</mechanicalReduction>
    </actuator>
    <joint name="lh_THJ2">
      <hardwareInterface>EffortJointInterface</hardwareInterface>
      <hardwareInterface>PositionJointInterface</hardwareInterface>
    </joint>
  </transmission>
  <gazebo reference="lh_thmiddle">
  </gazebo>
  <!-- common -->
  <link name="lh_thdistal">
    <inertial>
      <mass value="0.016"/>
      <origin rpy="0 0 0" xyz="0 0 0.01375"/>
      <inertia ixx="0.0000021" ixy="0.0" ixz="0.0" iyy="0.0000022" iyz="0.0" izz="0.000001"/>
    </inertial>
    <visual>
      <origin rpy="0 0 0" xyz="0 0 0"/>
      <geometry name="lh_thdistal_visual">
        <mesh filename="avatar_model/shadow_hand/meshes/collision_stl/thumb_distal.stl" scale="0.001 0.001 0.001"/>
      </geometry>
      <material name="shadow_thmiddle_material">
        <color rgba="0.2 0.2 0.2 1.0"/>
      </material>
    </visual>
    <collision>
      <origin rpy="0 0 0" xyz="0 0 0"/>
      <geometry name="lh_thmiddle_collision_geom">
        <mesh filename="avatar_model/shadow_hand/meshes/collision_stl/thumb_distal.stl" scale="0.001 0.001 0.001"/>
      </geometry>
    </collision>
  </link>
  <joint name="lh_THJ1" type="revolute">
    <parent link="lh_thmiddle"/>
    <child link="lh_thdistal"/>
    <origin rpy="0 0 0" xyz="0 0 0.032"/>
    <axis xyz="1 0 0"/>
    <limit effort="1.0" lower="-0.2617993877991494" upper="1.5707963267948966" velocity="4.0"/>
    <dynamics damping="0.2"/>
  </joint>
  <gazebo reference="lh_THJ1">
    <provideFeedback>1</provideFeedback>
    <implicitSpringDamper>1</implicitSpringDamper>
  </gazebo>
  <link name="lh_thtip">
    <inertial>
      <mass value="0.001"/>
      <inertia ixx="0.0" ixy="0.0" ixz="0.0" iyy="0.0" iyz="0.0" izz="0.0"/>
    </inertial>
  </link>
  <joint name="lh_thtip" type="fixed">
    <parent link="lh_thdistal"/>
    <child link="lh_thtip"/>
    <origin rpy="0 0 0" xyz="0 0 0.0275"/>
  </joint>
  <gazebo reference="lh_thdistal">
    <sensor name="lh_thdistal_contact" type="contact">
      <always_on>1</always_on>
      <update_rate>1000.0</update_rate>
      <contact>
        <collision>lh_thdistal_collision</collision>
        <topic>lh_thdistal_collision</topic>
      </contact>
      <plugin filename="libgazebo_ros_bumper.so" name="lh_thdistal_gazebo_ros_bumper_controller">
        <alwaysOn>true</alwaysOn>
        <frameName>lh_thdistal</frameName>
        <updateRate>100.0</updateRate>
        <bumperTopicName>contacts/lh_th/distal</bumperTopicName>
      </plugin>
    </sensor>
    <mu1 value="500.0"/>
    <mu2 value="500.0"/>
    <kp value="10000000.0"/>
    <kd value="1.0"/>
    <selfCollide>true</selfCollide>
  </gazebo>
  <transmission name="lh_thdistal_transmission">
    <type>sr_mechanism_model/SimpleTransmission</type>
    <actuator name="lh_THJ1">
      <mechanicalReduction>1</mechanicalReduction>
    </actuator>
    <joint name="lh_THJ1">
      <hardwareInterface>EffortJointInterface</hardwareInterface>
      <hardwareInterface>PositionJointInterface</hardwareInterface>
    </joint>
  </transmission>
  <!-- Conversion were obtained from http://www.e-paint.co.uk/Lab_values.asp
       unless otherwise stated. -->
  <!-- link list -->
  <link name="gofa2_base">
    <!-- See note 1 in package.xml about the inertial and mass values -->
    <inertial>
      <mass value="3.50083457958494"/>
      <origin xyz="-0.0012013793465437 -0.000175191786981708 0.0862146007385352"/>
      <inertia ixx="0.0153015257917955" ixy="-6.40155032892694E-05" ixz="-0.000276708687772683" iyy="0.0159333503953857" iyz="-3.98029144780725E-05" izz="0.0112162302268266"/>
    </inertial>
    <collision name="collision">
      <geometry>
        <mesh filename="avatar_model/abb_gofa/meshes/collision_stl/base.STL"/>
      </geometry>
    </collision>
    <visual name="visual">
      <geometry>
        <mesh filename="avatar_model/abb_gofa/meshes/visual_stl/base.STL"/>
      </geometry>
      <material name="">
        <color rgba="1 1 0 1"/>
      </material>
    </visual>
  </link>
  <link name="gofa2_link_1">
    <!-- See note 1 in package.xml about the inertial and mass values -->
    <inertial>
      <mass value="2.76743491139404"/>
      <origin xyz="2.08682453325091E-06 0.0103608399967513 0.0705307203199506"/>
      <inertia ixx="0.0115158625894577" ixy="6.37197693598838E-08" ixz="5.98954393680154E-09" iyy="0.006494848329231" iyz="-0.000196668400316843" izz="0.0109446835358581"/>
    </inertial>
    <collision name="collision">
      <geometry>
        <mesh filename="avatar_model/abb_gofa/meshes/collision_stl/link_1.STL"/>
      </geometry>
    </collision>
    <visual name="visual">
      <geometry>
        <mesh filename="avatar_model/abb_gofa/meshes/visual_stl/link_1.STL"/>
      </geometry>
      <material name="">
        <color rgba="1 1 0 1"/>
      </material>
    </visual>
  </link>
  <link name="gofa2_link_2">
    <!-- See note 1 in package.xml about the inertial and mass values -->
    <inertial>
      <mass value="4.2890416"/>
      <origin xyz="1.34018352211628E-06 -0.0500118376116071 0.222001399322246"/>
      <inertia ixx="0.130524729873898" ixy="1.31811857134115E-07" ixz="1.99022457670482E-06" iyy="0.133278449324229" iyz="-4.48622200366709E-07" izz="0.00669457974697178"/>
    </inertial>
    <collision name="collision">
      <geometry>
        <mesh filename="avatar_model/abb_gofa/meshes/collision_stl/link_2.STL"/>
      </geometry>
    </collision>
    <visual name="visual">
      <geometry>
        <mesh filename="avatar_model/abb_gofa/meshes/visual_stl/link_2.STL"/>
      </geometry>
      <material name="">
        <color rgba="1 1 0 1"/>
      </material>
    </visual>
  </link>
  <link name="gofa2_link_3">
    <!-- See note 1 in package.xml about the inertial and mass values -->
    <inertial>
      <mass value="3.38333107992875"/>
      <origin xyz="0.0128129281453599 0.0944171780907046 0.0247427540642403"/>
      <inertia ixx="0.0175626138728642" ixy="0.000364866179108744" ixz="-0.00318670290285352" iyy="0.0140230068919562" iyz="0.000704668055158407" izz="0.013275205067567"/>
    </inertial>
    <collision name="collision">
      <geometry>
        <mesh filename="avatar_model/abb_gofa/meshes/collision_stl/link_3.STL"/>
      </geometry>
    </collision>
    <visual name="visual">
      <geometry>
        <mesh filename="avatar_model/abb_gofa/meshes/visual_stl/link_3.STL"/>
      </geometry>
      <material name="">
        <color rgba="1 1 0 1"/>
      </material>
    </visual>
  </link>
  <link name="gofa2_link_4">
    <!-- See note 1 in package.xml about the inertial and mass values -->
    <inertial>
      <mass value="2.77857535641324"/>
      <origin xyz="0.160558561602322 0.041976811408979 -2.36623354021859E-07"/>
      <inertia ixx="0.00881683095901354" ixy="-0.010746260580237" ixz="1.2899930119841E-07" iyy="0.0340754175571832" iyz="3.96362791626429E-08" izz="0.0389358932156922"/>
    </inertial>
    <collision name="collision">
      <geometry>
        <mesh filename="avatar_model/abb_gofa/meshes/collision_stl/link_4.STL"/>
      </geometry>
    </collision>
    <visual name="visual">
      <geometry>
        <mesh filename="avatar_model/abb_gofa/meshes/visual_stl/link_4.STL"/>
      </geometry>
      <material name="">
        <color rgba="1 1 0 1"/>
      </material>
    </visual>
  </link>
  <link name="gofa2_link_5">
    <!-- See note 1 in package.xml about the inertial and mass values -->
    <inertial>
      <mass value="3.01105814739001"/>
      <origin xyz="-0.0147152361879962 -0.0785646469392633 0.0427558021601431"/>
      <inertia ixx="0.0114597336686444" ixy="0.000180094704361231" ixz="0.00165207280226761" iyy="0.013561904467501" iyz="-0.000525272443978826" izz="0.0108480119549914"/>
    </inertial>
    <collision name="collision">
      <geometry>
        <mesh filename="avatar_model/abb_gofa/meshes/collision_stl/link_5.STL"/>
      </geometry>
    </collision>
    <visual name="visual">
      <geometry>
        <mesh filename="avatar_model/abb_gofa/meshes/visual_stl/link_5.STL"/>
      </geometry>
      <material name="">
        <color rgba="1 1 0 1"/>
      </material>
    </visual>
  </link>
  <link name="gofa2_link_6">
    <!-- See note 1 in package.xml about the inertial and mass values -->
    <inertial>
      <mass value="0.146500988015653"/>
      <origin rpy="0 0 0" xyz="0.0137506852604966 0.000239804131398652 -0.000341962798940165"/>
      <inertia ixx="0.000128977630055306" ixy="-8.7622752508613E-08" ixz="1.18851551870012E-07" iyy="7.61118177829087E-05" iyz="-6.49821554399679E-07" izz="7.65022909768016E-05"/>
    </inertial>
    <!-- Meshlab calculated values (below) make gazebo crash when rotating this joint. -->
    <!-- <inertial>
        <mass value="0.00686711"/>
        <origin xyz="-0.00250976 -1.89e-06 0.00010218"/>
        <inertia ixx="1.3517e-06" ixy="-1.21316e-11" ixz="9.18065e-12" iyy="6.89813e-07" iyz="-1.21534e-10" izz="6.90097e-07"/>
      </inertial> -->
    <collision name="collision">
      <geometry>
        <mesh filename="avatar_model/abb_gofa/meshes/collision_stl/link_6.STL"/>
      </geometry>
    </collision>
    <visual name="visual">
      <geometry>
        <mesh filename="avatar_model/abb_gofa/meshes/visual_stl/link_6.STL"/>
      </geometry>
      <material name="">
        <color rgba="1 1 0 1"/>
      </material>
    </visual>
  </link>
  <!-- end of link list -->
  <!-- joint list -->
  <joint name="gofa2_joint_1" type="revolute">
    <origin rpy="0 0 0" xyz="0 0 0.1875"/>
    <axis xyz="0 0 1"/>
    <parent link="gofa2_base"/>
    <child link="gofa2_link_1"/>
    <!-- See note 2 in package.xml about effort limits and dynamics values -->
    <limit effort="1000" lower="-2.967" upper="2.967" velocity="5.027"/>
    <dynamics damping="50.0" friction="1.0"/>
  </joint>
  <joint name="gofa2_joint_2" type="revolute">
    <origin rpy="0 0 0" xyz="0 -0.085 0.0775"/>
    <axis xyz="0 1 0"/>
    <parent link="gofa2_link_1"/>
    <child link="gofa2_link_2"/>
    <!-- See note 2 in package.xml about effort limits and dynamics values -->
    <limit effort="1000" lower="-1.745" upper="2.269" velocity="4.189"/>
    <dynamics damping="50.0" friction="1.0"/>
  </joint>
  <joint name="gofa2_joint_3" type="revolute">
    <origin rpy="0 0 0" xyz="0 -0.00100000000000007 0.444"/>
    <axis xyz="0 1 0"/>
    <parent link="gofa2_link_2"/>
    <child link="gofa2_link_3"/>
    <!-- See note 2 in package.xml about effort limits and dynamics values -->
    <limit effort="1000" lower="-3.491" upper="1.222" velocity="5.236"/>
    <dynamics damping="10.0" friction="1.0"/>
  </joint>
  <joint name="gofa2_joint_4" type="revolute">
    <origin rpy="0 0 0" xyz="0.096 0.0860000000000001 0.11"/>
    <axis xyz="1 0 0"/>
    <parent link="gofa2_link_3"/>
    <child link="gofa2_link_4"/>
    <!-- See note 2 in package.xml about effort limits and dynamics values -->
    <limit effort="1000" lower="-4.712" upper="4.712" velocity="6.981"/>
    <dynamics damping="5.0" friction="1.0"/>
  </joint>
  <joint name="gofa2_joint_5" type="revolute">
    <origin rpy="0 0 0" xyz="0.374 0.0744999999999998 0"/>
    <axis xyz="0 1 0"/>
    <parent link="gofa2_link_4"/>
    <child link="gofa2_link_5"/>
    <!-- See note 2 in package.xml about effort limits and dynamics values -->
    <limit effort="1000" lower="-2.269" upper="2.269" velocity="7.069"/>
    <dynamics damping="2.0" friction="1.0"/>
  </joint>
  <joint name="gofa2_joint_6" type="revolute">
    <origin rpy="0 0 0" xyz="0.0679999999999995 -0.0744999999999998 0.0800000000000003"/>
    <axis xyz="1 0 0"/>
    <parent link="gofa2_link_5"/>
    <child link="gofa2_link_6"/>
    <!-- See note 2 in package.xml about effort limits and dynamics values -->
    <limit effort="1000" lower="-6.283" upper="6.283" velocity="10.472"/>
    <dynamics damping="1.0" friction="1.0"/>
  </joint>
  <!-- end of joint list -->
  <!-- ROS-Industrial 'base' frame- base_link to ABB World Coordinates transform -->
  <link name="gofa2_base_link"/>
  <joint name="gofa2_base_link-base" type="fixed">
    <origin rpy="0 0 0" xyz="0 0 0"/>
    <parent link="gofa2_base_link"/>
    <child link="gofa2_base"/>
  </joint>
  <!-- ROS-Industrial 'tool0' frame- all-zeros tool frame -->
  <link name="gofa2_tool0"/>
  <joint name="gofa2_link_6-tool0" type="fixed">
    <origin rpy="0 1.5708 0" xyz="0.0326 0 0"/>
    <parent link="gofa2_link_6"/>
    <child link="gofa2_tool0"/>
  </joint>
  <joint name="rh_world_joint" type="fixed">
    <parent link="gofa2_tool0"/>
    <child link="rh_forearm"/>
    <origin rpy="0.0 0.0 3.14" xyz="0.0 0.0 0.007"/>
  </joint>
  <link name="rh_forearm">
    <inertial>
      <origin rpy="0 0 0" xyz="0 0 0.09"/>
      <mass value="3.0"/>
      <inertia ixx="0.0138" ixy="0.0" ixz="0.0" iyy="0.0138" iyz="0.0" izz="0.00744"/>
    </inertial>
    <visual>
      <origin rpy="0 0 0" xyz="0 0 0.0"/>
      <geometry name="rh_forearm_visual">
        <mesh filename="avatar_model/shadow_hand/meshes/collision_stl/forearm.stl" scale="0.001 0.001 0.001"/>
      </geometry>
      <material name="light_grey">
        <color rgba="0.90000 0.90000 0.90000 1.0"/>
      </material>
    </visual>
    <collision>
      <origin rpy="0 0 0" xyz="0 0 0.0"/>
      <geometry name="rh_forearm_collision">
        <mesh filename="avatar_model/shadow_hand/meshes/collision_stl/forearm.stl" scale="0.001 0.001 0.001"/>
      </geometry>
    </collision>
    <!-- wrist mount -->
    <collision>
      <origin rpy="0 0.78 0" xyz="0 -0.01 0.181"/>
      <geometry>
        <box size="0.07 0.07 0.07"/>
      </geometry>
    </collision>
    <!-- TODO: Make a decision on whether to add the connector or not -->
    <!--visual>
        <origin rpy="0 -1.57 -1.57" xyz="0.0 0.067 0.0045"/>
        <geometry name="${prefix}cable_extr_visualisation">
          <mesh filename="avatar_model/shadow_hand/meshes/collision_obj/cable_connector/cable_connector_base_${hand_version}.dae" scale="0.001 0.001 0.001" />
        </geometry>
      </visual-->
  </link>
  <gazebo reference="rh_forearm">
    <selfCollide>false</selfCollide>
  </gazebo>
  <link name="rh_wrist">
    <inertial>
      <origin rpy="0 0 0" xyz="0 0 0.029"/>
      <mass value="0.1"/>
      <inertia ixx="0.000035" ixy="0.0" ixz="0.0" iyy="0.000064" iyz="0.0" izz="0.0000438"/>
    </inertial>
    <visual>
      <origin rpy="0 0 0" xyz="0 0 0"/>
      <geometry name="rh_wrist_visual">
        <mesh filename="avatar_model/shadow_hand/meshes/collision_stl/wrist.stl" scale="0.001 0.001 0.001"/>
      </geometry>
      <material name="LightGrey"/>
    </visual>
    <collision>
      <origin rpy="1.5708 1.5708 0" xyz="0 0 0"/>
      <geometry name="rh_wrist_collision_geom">
        <cylinder length="0.030" radius="0.0135"/>
      </geometry>
    </collision>
    <collision>
      <origin rpy="0 1.5708 0" xyz="-0.026 0 0.034"/>
      <geometry>
        <cylinder length="0.010" radius="0.011"/>
      </geometry>
    </collision>
    <collision>
      <origin rpy="0 1.5708 0" xyz="0.031 0 0.034"/>
      <geometry>
        <cylinder length="0.010" radius="0.011"/>
      </geometry>
    </collision>
    <collision>
      <origin rpy="0 0.7854 0" xyz="-0.021 0 0.011"/>
      <geometry>
        <box size="0.027 0.018 0.010"/>
      </geometry>
    </collision>
    <collision>
      <origin rpy="0 -0.7854 0" xyz="0.026 0 0.010"/>
      <geometry>
        <box size="0.027 0.018 0.010"/>
      </geometry>
    </collision>
  </link>
  <gazebo reference="rh_wrist">
    <material>Gazebo/White</material>
    <selfCollide>false</selfCollide>
  </gazebo>
  <joint name="rh_WRJ2" type="revolute">
    <parent link="rh_forearm"/>
    <child link="rh_wrist"/>
    <origin rpy="0 0 0" xyz="0 -0.010 0.21301"/>
    <axis xyz="0 1 0"/>
    <limit effort="10" lower="-0.5235987755982988" upper="0.17453292519943295" velocity="2.0"/>
    <dynamics damping="0.1"/>
  </joint>
  <gazebo reference="rh_WRJ2">
    <provideFeedback>1</provideFeedback>
    <implicitSpringDamper>1</implicitSpringDamper>
  </gazebo>
  <transmission name="rh_wrist_transmission">
    <type>sr_mechanism_model/SimpleTransmission</type>
    <actuator name="rh_WRJ2">
      <mechanicalReduction>1</mechanicalReduction>
    </actuator>
    <joint name="rh_WRJ2">
      <hardwareInterface>EffortJointInterface</hardwareInterface>
      <hardwareInterface>PositionJointInterface</hardwareInterface>
    </joint>
  </transmission>
  <link name="rh_palm">
    <inertial>
      <origin rpy="0 0 0" xyz="0 0 0.035"/>
      <mass value="0.3"/>
      <inertia ixx="0.0003581" ixy="0.0" ixz="0.0" iyy="0.0005287" iyz="0.0" izz="0.000191"/>
    </inertial>
    <visual>
      <origin rpy="0 0 0" xyz="0 0 0"/>
      <geometry name="rh_palm_visual">
        <mesh filename="avatar_model/shadow_hand/meshes/collision_stl/palm.stl" scale="0.001 0.001 0.001"/>
      </geometry>
      <material name="Grey"/>
    </visual>
    <collision>
      <origin rpy="0 0 0" xyz="0.011 0.0085 0.038"/>
      <geometry name="rh_palm_collision_geom">
        <box size="0.062 0.007 0.098"/>
      </geometry>
    </collision>
    <collision>
      <origin rpy="0 0 0" xyz="-0.002 -0.0035 0.038"/>
      <geometry>
        <box size="0.036 0.017 0.098"/>
      </geometry>
    </collision>
    <!-- palm complement below first finger -->
    <collision>
      <origin rpy="0 0 0" xyz="0.029 -0.0035 0.082"/>
      <geometry>
        <box size="0.026 0.017 0.010"/>
      </geometry>
    </collision>
    <collision>
      <origin rpy="0.2 0 0.25" xyz="0.0265 -0.001 0.070"/>
      <geometry>
        <box size="0.026 0.014 0.018"/>
      </geometry>
    </collision>
    <!-- thumb pulp side -->
    <collision>
      <origin rpy="0 0 0" xyz="0.0315 -0.0085 0.001"/>
      <geometry>
        <box size="0.021 0.027 0.024"/>
      </geometry>
    </collision>
    <!-- thumb pulp central -->
    <collision>
      <origin rpy="0 0 -0.48" xyz="0.0125 -0.015 0.009"/>
      <geometry>
        <box size="0.022 0.005 0.040"/>
      </geometry>
    </collision>
    <!-- above middle finger-->
    <collision>
      <origin rpy="0 0 0" xyz="0.011 0 0.089"/>
      <geometry>
        <box size="0.018 0.024 0.004"/>
      </geometry>
    </collision>
    <!-- metacarpal side-->
    <collision>
      <origin rpy="0 0 0" xyz="-0.03 0 0.009"/>
      <geometry>
        <box size="0.020 0.024 0.040"/>
      </geometry>
    </collision>
  </link>
  <joint name="rh_ee_fixed_joint" type="fixed">
    <parent link="rh_palm"/>
    <child link="rh_manipulator"/>
    <origin rpy="0.0 0.0 0.0" xyz="0.0 0.0 0.05"/>
  </joint>
  <link name="rh_manipulator"/>
  <joint name="rh_WRJ1" type="revolute">
    <parent link="rh_wrist"/>
    <child link="rh_palm"/>
    <origin rpy="0 0 0" xyz="0 0 0.034"/>
    <axis xyz="1 0 0"/>
    <limit effort="30" lower="-0.6981317007977318" upper="0.4886921905584123" velocity="2.0"/>
    <dynamics damping="0.1"/>
  </joint>
  <gazebo reference="rh_WRJ1">
    <provideFeedback>1</provideFeedback>
    <implicitSpringDamper>1</implicitSpringDamper>
  </gazebo>
  <link name="rh_imu"/>
  <joint name="rh_palm_to_imu" type="fixed">
    <parent link="rh_palm"/>
    <child link="rh_imu"/>
    <origin rpy="-1.5707963 3.141592 0.0" xyz="0.01785 0.00765 0.049125"/>
  </joint>
  <transmission name="rh_palm_transmission">
    <type>sr_mechanism_model/SimpleTransmission</type>
    <actuator name="rh_WRJ1">
      <mechanicalReduction>1</mechanicalReduction>
    </actuator>
    <joint name="rh_WRJ1">
      <hardwareInterface>EffortJointInterface</hardwareInterface>
      <hardwareInterface>PositionJointInterface</hardwareInterface>
    </joint>
  </transmission>
  <gazebo reference="rh_palm">
  </gazebo>
  <link name="rh_ffknuckle">
    <inertial>
      <origin rpy="0 0 0" xyz="0 0 0"/>
      <mass value="0.008"/>
      <inertia ixx="0.00000026" ixy="0.0" ixz="0.0" iyy="0.00000026" iyz="0.0" izz="0.00000032"/>
    </inertial>
    <visual>
      <origin rpy="0 0 0" xyz="0 0 0.0005"/>
      <geometry name="rh_ffknuckle_visual">
        <mesh filename="avatar_model/shadow_hand/meshes/collision_stl/knuckle.stl" scale="0.001 0.001 0.001"/>
      </geometry>
      <material name="LightGrey"/>
    </visual>
    <collision>
      <origin rpy="0 1.5708 0" xyz="0 0 0"/>
      <geometry name="rh_ffknuckle_collision_geom">
        <cylinder length="0.014" radius="0.007"/>
      </geometry>
    </collision>
  </link>
  <joint name="rh_FFJ4" type="revolute">
    <parent link="rh_palm"/>
    <child link="rh_ffknuckle"/>
    <!--<origin xyz="0.033 0 0.095" rpy="0 0 0" />-->
    <origin rpy="0 0 0" xyz="0.033 0 0.095"/>
    <axis xyz="0 -1 0"/>
    <limit effort="2" lower="-0.3490658503988659" upper="0.3490658503988659" velocity="2.0"/>
    <dynamics damping="0.1"/>
  </joint>
  <gazebo reference="rh_FFJ4">
    <provideFeedback>1</provideFeedback>
    <implicitSpringDamper>1</implicitSpringDamper>
  </gazebo>
  <transmission name="rh_ffknuckle_transmission">
    <type>sr_mechanism_model/SimpleTransmission</type>
    <actuator name="rh_FFJ4">
      <mechanicalReduction>1</mechanicalReduction>
    </actuator>
    <joint name="rh_FFJ4">
      <hardwareInterface>EffortJointInterface</hardwareInterface>
      <hardwareInterface>PositionJointInterface</hardwareInterface>
    </joint>
  </transmission>
  <gazebo reference="rh_ffknuckle">
    <!-- knuckle is not highly exposed, so bumper is not useful -->
    <material>Gazebo/Grey</material>
  </gazebo>
  <link name="rh_ffproximal">
    <inertial>
      <mass value="0.030"/>
      <origin xyz="0 0 0.0225"/>
      <inertia ixx="0.0000098" ixy="0.0" ixz="0.0" iyy="0.00001" iyz="0.0" izz="0.0000018"/>
    </inertial>
    <visual>
      <origin rpy="0 0 0" xyz="0 0 0"/>
      <geometry name="rh_ffproximal_visual">
        <mesh filename="avatar_model/shadow_hand/meshes/collision_stl/finger_proximal.stl" scale="0.001 0.001 0.001"/>
      </geometry>
      <material name="Grey"/>
    </visual>
    <collision>
      <origin rpy="0 0 0" xyz="0 0 0.025"/>
      <geometry name="rh_ffproximal_collision_geom">
        <cylinder length="0.040" radius="0.007"/>
      </geometry>
    </collision>
  </link>
  <joint name="rh_FFJ3" type="revolute">
    <parent link="rh_ffknuckle"/>
    <child link="rh_ffproximal"/>
    <origin rpy="0 0 0" xyz="0 0 0"/>
    <axis xyz="1 0 0"/>
    <limit effort="2" lower="-0.2617993877991494" upper="1.5707963267948966" velocity="2.0"/>
    <dynamics damping="0.1"/>
  </joint>
  <gazebo reference="rh_FFJ3">
    <provideFeedback>1</provideFeedback>
    <implicitSpringDamper>1</implicitSpringDamper>
  </gazebo>
  <transmission name="rh_ffproximal_transmission">
    <type>sr_mechanism_model/SimpleTransmission</type>
    <actuator name="rh_FFJ3">
      <mechanicalReduction>1</mechanicalReduction>
    </actuator>
    <joint name="rh_FFJ3">
      <hardwareInterface>EffortJointInterface</hardwareInterface>
      <hardwareInterface>PositionJointInterface</hardwareInterface>
    </joint>
  </transmission>
  <gazebo reference="rh_ffproximal">
    <selfCollide>true</selfCollide>
  </gazebo>
  <link name="rh_ffmiddle">
    <inertial>
      <origin rpy="0 0 0" xyz="0 0 0.0125"/>
      <mass value="0.017"/>
      <inertia ixx="0.0000026" ixy="0.0" ixz="0.0" iyy="0.0000027" iyz="0.0" izz="0.00000087"/>
    </inertial>
    <visual>
      <origin rpy="0 0 0" xyz="0 0 0"/>
      <geometry name="rh_ffmiddle_visual">
        <mesh filename="avatar_model/shadow_hand/meshes/collision_stl/finger_middle.stl" scale="0.001 0.001 0.001"/>
      </geometry>
      <material name="Grey"/>
    </visual>
    <collision>
      <origin rpy="0 0 0" xyz="0 0 0.0125"/>
      <geometry name="rh_ffmiddle_collision_geom">
        <cylinder length="0.025" radius="0.007"/>
      </geometry>
    </collision>
    <collision>
      <origin rpy="0 0 0" xyz="0 0 0.0"/>
      <geometry>
        <sphere radius="0.007"/>
      </geometry>
    </collision>
    <collision>
      <origin rpy="0 0 0" xyz="0 0 0.025"/>
      <geometry>
        <sphere radius="0.007"/>
      </geometry>
    </collision>
  </link>
  <joint name="rh_FFJ2" type="revolute">
    <parent link="rh_ffproximal"/>
    <child link="rh_ffmiddle"/>
    <origin rpy="0 0 0" xyz="0 0 0.045"/>
    <axis xyz="1 0 0"/>
    <limit effort="2" lower="0" upper="1.5707963267948966" velocity="2.0"/>
    <dynamics damping="0.1"/>
  </joint>
  <gazebo reference="rh_FFJ2">
    <provideFeedback>1</provideFeedback>
    <implicitSpringDamper>1</implicitSpringDamper>
  </gazebo>
  <transmission name="rh_ffmiddle_transmission">
    <type>sr_mechanism_model/J0Transmission</type>
    <actuator name="rh_FFJ0">
      <mechanicalReduction>1</mechanicalReduction>
    </actuator>
    <joint name="rh_FFJ1">
      <hardwareInterface>EffortJointInterface</hardwareInterface>
      <hardwareInterface>PositionJointInterface</hardwareInterface>
    </joint>
  </transmission>
  <gazebo reference="rh_ffmiddle">
    <selfCollide>true</selfCollide>
  </gazebo>
  <link name="rh_ffdistal">
    <inertial>
      <mass value="0.012"/>
      <origin xyz="0 0 0.012"/>
      <inertia ixx="0.00000094" ixy="0.0" ixz="0.0" iyy="0.0000011" iyz="0.0" izz="0.00000053"/>
    </inertial>
    <visual>
      <origin rpy="0 0 0" xyz="0 0 0"/>
      <geometry name="rh_ffdistal_visual">
        <mesh filename="avatar_model/shadow_hand/meshes/collision_stl/finger_distal.stl" scale="0.001 0.001 0.001"/>
      </geometry>
    </visual>
    <collision>
      <origin rpy="0 0 0" xyz="0 0 0"/>
      <geometry name="rh_ffdistal_collision_geom">
        <mesh filename="avatar_model/shadow_hand/meshes/collision_stl/finger_distal.stl" scale="0.001 0.001 0.001"/>
      </geometry>
    </collision>
  </link>
  <joint name="rh_FFJ1" type="revolute">
    <parent link="rh_ffmiddle"/>
    <child link="rh_ffdistal"/>
    <origin rpy="0 0 0" xyz="0 0 0.025"/>
    <axis xyz="1 0 0"/>
    <!-- standard distal joint -->
    <limit effort="2" lower="0" upper="1.5707963267948966" velocity="2.0"/>
    <dynamics damping="0.1"/>
  </joint>
  <gazebo reference="rh_FFJ1">
    <provideFeedback>1</provideFeedback>
    <implicitSpringDamper>1</implicitSpringDamper>
  </gazebo>
  <link name="rh_fftip">
    <inertial>
      <mass value="0.001"/>
      <inertia ixx="0.0" ixy="0.0" ixz="0.0" iyy="0.0" iyz="0.0" izz="0.0"/>
    </inertial>
  </link>
  <joint name="rh_FFtip" type="fixed">
    <parent link="rh_ffdistal"/>
    <child link="rh_fftip"/>
    <origin rpy="0 0 0" xyz="0 0 0.026"/>
  </joint>
  <gazebo reference="rh_ffdistal">
    <sensor name="rh_ffdistal_contact" type="contact">
      <always_on>1</always_on>
      <update_rate>1000.0</update_rate>
      <contact>
        <collision>rh_ffdistal_collision</collision>
        <topic>rh_ffdistal_collision</topic>
      </contact>
      <plugin filename="libgazebo_ros_bumper.so" name="rh_ffdistal_gazebo_ros_bumper_controller">
        <alwaysOn>true</alwaysOn>
        <frameName>rh_ffdistal</frameName>
        <updateRate>100.0</updateRate>
        <bumperTopicName>contacts/rh_ff/distal</bumperTopicName>
      </plugin>
    </sensor>
    <mu1 value="500.0"/>
    <mu2 value="500.0"/>
    <kp value="10000000.0"/>
    <kd value="1.0"/>
    <selfCollide>true</selfCollide>
  </gazebo>
  <link name="rh_mfknuckle">
    <inertial>
      <origin rpy="0 0 0" xyz="0 0 0"/>
      <mass value="0.008"/>
      <inertia ixx="0.00000026" ixy="0.0" ixz="0.0" iyy="0.00000026" iyz="0.0" izz="0.00000032"/>
    </inertial>
    <visual>
      <origin rpy="0 0 0" xyz="0 0 0.0005"/>
      <geometry name="rh_mfknuckle_visual">
        <mesh filename="avatar_model/shadow_hand/meshes/collision_stl/knuckle.stl" scale="0.001 0.001 0.001"/>
      </geometry>
      <material name="LightGrey"/>
    </visual>
    <collision>
      <origin rpy="0 1.5708 0" xyz="0 0 0"/>
      <geometry name="rh_mfknuckle_collision_geom">
        <cylinder length="0.014" radius="0.007"/>
      </geometry>
    </collision>
  </link>
  <joint name="rh_MFJ4" type="revolute">
    <parent link="rh_palm"/>
    <child link="rh_mfknuckle"/>
    <!--<origin xyz="0.033 0 0.095" rpy="0 0 0" />-->
    <origin rpy="0 0 0" xyz="0.011 0 0.099"/>
    <axis xyz="0 -1 0"/>
    <limit effort="2" lower="-0.3490658503988659" upper="0.3490658503988659" velocity="2.0"/>
    <dynamics damping="0.1"/>
  </joint>
  <gazebo reference="rh_MFJ4">
    <provideFeedback>1</provideFeedback>
    <implicitSpringDamper>1</implicitSpringDamper>
  </gazebo>
  <transmission name="rh_mfknuckle_transmission">
    <type>sr_mechanism_model/SimpleTransmission</type>
    <actuator name="rh_MFJ4">
      <mechanicalReduction>1</mechanicalReduction>
    </actuator>
    <joint name="rh_MFJ4">
      <hardwareInterface>EffortJointInterface</hardwareInterface>
      <hardwareInterface>PositionJointInterface</hardwareInterface>
    </joint>
  </transmission>
  <gazebo reference="rh_mfknuckle">
    <!-- knuckle is not highly exposed, so bumper is not useful -->
    <material>Gazebo/Grey</material>
  </gazebo>
  <link name="rh_mfproximal">
    <inertial>
      <mass value="0.030"/>
      <origin xyz="0 0 0.0225"/>
      <inertia ixx="0.0000098" ixy="0.0" ixz="0.0" iyy="0.00001" iyz="0.0" izz="0.0000018"/>
    </inertial>
    <visual>
      <origin rpy="0 0 0" xyz="0 0 0"/>
      <geometry name="rh_mfproximal_visual">
        <mesh filename="avatar_model/shadow_hand/meshes/collision_stl/finger_proximal.stl" scale="0.001 0.001 0.001"/>
      </geometry>
      <material name="Grey"/>
    </visual>
    <collision>
      <origin rpy="0 0 0" xyz="0 0 0.025"/>
      <geometry name="rh_mfproximal_collision_geom">
        <cylinder length="0.040" radius="0.007"/>
      </geometry>
    </collision>
  </link>
  <joint name="rh_MFJ3" type="revolute">
    <parent link="rh_mfknuckle"/>
    <child link="rh_mfproximal"/>
    <origin rpy="0 0 0" xyz="0 0 0"/>
    <axis xyz="1 0 0"/>
    <limit effort="2" lower="-0.2617993877991494" upper="1.5707963267948966" velocity="2.0"/>
    <dynamics damping="0.1"/>
  </joint>
  <gazebo reference="rh_MFJ3">
    <provideFeedback>1</provideFeedback>
    <implicitSpringDamper>1</implicitSpringDamper>
  </gazebo>
  <transmission name="rh_mfproximal_transmission">
    <type>sr_mechanism_model/SimpleTransmission</type>
    <actuator name="rh_MFJ3">
      <mechanicalReduction>1</mechanicalReduction>
    </actuator>
    <joint name="rh_MFJ3">
      <hardwareInterface>EffortJointInterface</hardwareInterface>
      <hardwareInterface>PositionJointInterface</hardwareInterface>
    </joint>
  </transmission>
  <gazebo reference="rh_mfproximal">
    <selfCollide>true</selfCollide>
  </gazebo>
  <link name="rh_mfmiddle">
    <inertial>
      <origin rpy="0 0 0" xyz="0 0 0.0125"/>
      <mass value="0.017"/>
      <inertia ixx="0.0000026" ixy="0.0" ixz="0.0" iyy="0.0000027" iyz="0.0" izz="0.00000087"/>
    </inertial>
    <visual>
      <origin rpy="0 0 0" xyz="0 0 0"/>
      <geometry name="rh_mfmiddle_visual">
        <mesh filename="avatar_model/shadow_hand/meshes/collision_stl/finger_middle.stl" scale="0.001 0.001 0.001"/>
      </geometry>
      <material name="Grey"/>
    </visual>
    <collision>
      <origin rpy="0 0 0" xyz="0 0 0.0125"/>
      <geometry name="rh_mfmiddle_collision_geom">
        <cylinder length="0.025" radius="0.007"/>
      </geometry>
    </collision>
    <collision>
      <origin rpy="0 0 0" xyz="0 0 0.0"/>
      <geometry>
        <sphere radius="0.007"/>
      </geometry>
    </collision>
    <collision>
      <origin rpy="0 0 0" xyz="0 0 0.025"/>
      <geometry>
        <sphere radius="0.007"/>
      </geometry>
    </collision>
  </link>
  <joint name="rh_MFJ2" type="revolute">
    <parent link="rh_mfproximal"/>
    <child link="rh_mfmiddle"/>
    <origin rpy="0 0 0" xyz="0 0 0.045"/>
    <axis xyz="1 0 0"/>
    <limit effort="2" lower="0" upper="1.5707963267948966" velocity="2.0"/>
    <dynamics damping="0.1"/>
  </joint>
  <gazebo reference="rh_MFJ2">
    <provideFeedback>1</provideFeedback>
    <implicitSpringDamper>1</implicitSpringDamper>
  </gazebo>
  <transmission name="rh_mfmiddle_transmission">
    <type>sr_mechanism_model/J0Transmission</type>
    <actuator name="rh_MFJ0">
      <mechanicalReduction>1</mechanicalReduction>
    </actuator>
    <joint name="rh_MFJ1">
      <hardwareInterface>EffortJointInterface</hardwareInterface>
      <hardwareInterface>PositionJointInterface</hardwareInterface>
    </joint>
  </transmission>
  <gazebo reference="rh_mfmiddle">
    <selfCollide>true</selfCollide>
  </gazebo>
  <link name="rh_mfdistal">
    <inertial>
      <mass value="0.012"/>
      <origin xyz="0 0 0.012"/>
      <inertia ixx="0.00000094" ixy="0.0" ixz="0.0" iyy="0.0000011" iyz="0.0" izz="0.00000053"/>
    </inertial>
    <visual>
      <origin rpy="0 0 0" xyz="0 0 0"/>
      <geometry name="rh_mfdistal_visual">
        <mesh filename="avatar_model/shadow_hand/meshes/collision_stl/finger_distal.stl" scale="0.001 0.001 0.001"/>
      </geometry>
    </visual>
    <collision>
      <origin rpy="0 0 0" xyz="0 0 0"/>
      <geometry name="rh_mfdistal_collision_geom">
        <mesh filename="avatar_model/shadow_hand/meshes/collision_stl/finger_distal.stl" scale="0.001 0.001 0.001"/>
      </geometry>
    </collision>
  </link>
  <joint name="rh_MFJ1" type="revolute">
    <parent link="rh_mfmiddle"/>
    <child link="rh_mfdistal"/>
    <origin rpy="0 0 0" xyz="0 0 0.025"/>
    <axis xyz="1 0 0"/>
    <!-- standard distal joint -->
    <limit effort="2" lower="0" upper="1.5707963267948966" velocity="2.0"/>
    <dynamics damping="0.1"/>
  </joint>
  <gazebo reference="rh_MFJ1">
    <provideFeedback>1</provideFeedback>
    <implicitSpringDamper>1</implicitSpringDamper>
  </gazebo>
  <link name="rh_mftip">
    <inertial>
      <mass value="0.001"/>
      <inertia ixx="0.0" ixy="0.0" ixz="0.0" iyy="0.0" iyz="0.0" izz="0.0"/>
    </inertial>
  </link>
  <joint name="rh_MFtip" type="fixed">
    <parent link="rh_mfdistal"/>
    <child link="rh_mftip"/>
    <origin rpy="0 0 0" xyz="0 0 0.026"/>
  </joint>
  <gazebo reference="rh_mfdistal">
    <sensor name="rh_mfdistal_contact" type="contact">
      <always_on>1</always_on>
      <update_rate>1000.0</update_rate>
      <contact>
        <collision>rh_mfdistal_collision</collision>
        <topic>rh_mfdistal_collision</topic>
      </contact>
      <plugin filename="libgazebo_ros_bumper.so" name="rh_mfdistal_gazebo_ros_bumper_controller">
        <alwaysOn>true</alwaysOn>
        <frameName>rh_mfdistal</frameName>
        <updateRate>100.0</updateRate>
        <bumperTopicName>contacts/rh_mf/distal</bumperTopicName>
      </plugin>
    </sensor>
    <mu1 value="500.0"/>
    <mu2 value="500.0"/>
    <kp value="10000000.0"/>
    <kd value="1.0"/>
    <selfCollide>true</selfCollide>
  </gazebo>
  <link name="rh_rfknuckle">
    <inertial>
      <origin rpy="0 0 0" xyz="0 0 0"/>
      <mass value="0.008"/>
      <inertia ixx="0.00000026" ixy="0.0" ixz="0.0" iyy="0.00000026" iyz="0.0" izz="0.00000032"/>
    </inertial>
    <visual>
      <origin rpy="0 0 0" xyz="0 0 0.0005"/>
      <geometry name="rh_rfknuckle_visual">
        <mesh filename="avatar_model/shadow_hand/meshes/collision_stl/knuckle.stl" scale="0.001 0.001 0.001"/>
      </geometry>
      <material name="LightGrey"/>
    </visual>
    <collision>
      <origin rpy="0 1.5708 0" xyz="0 0 0"/>
      <geometry name="rh_rfknuckle_collision_geom">
        <cylinder length="0.014" radius="0.007"/>
      </geometry>
    </collision>
  </link>
  <joint name="rh_RFJ4" type="revolute">
    <parent link="rh_palm"/>
    <child link="rh_rfknuckle"/>
    <!--<origin xyz="0.033 0 0.095" rpy="0 0 0" />-->
    <origin rpy="0 0 0" xyz="-0.011 0 0.095"/>
    <axis xyz="0 1 0"/>
    <limit effort="2" lower="-0.3490658503988659" upper="0.3490658503988659" velocity="2.0"/>
    <dynamics damping="0.1"/>
  </joint>
  <gazebo reference="rh_RFJ4">
    <provideFeedback>1</provideFeedback>
    <implicitSpringDamper>1</implicitSpringDamper>
  </gazebo>
  <transmission name="rh_rfknuckle_transmission">
    <type>sr_mechanism_model/SimpleTransmission</type>
    <actuator name="rh_RFJ4">
      <mechanicalReduction>1</mechanicalReduction>
    </actuator>
    <joint name="rh_RFJ4">
      <hardwareInterface>EffortJointInterface</hardwareInterface>
      <hardwareInterface>PositionJointInterface</hardwareInterface>
    </joint>
  </transmission>
  <gazebo reference="rh_rfknuckle">
    <!-- knuckle is not highly exposed, so bumper is not useful -->
    <material>Gazebo/Grey</material>
  </gazebo>
  <link name="rh_rfproximal">
    <inertial>
      <mass value="0.030"/>
      <origin xyz="0 0 0.0225"/>
      <inertia ixx="0.0000098" ixy="0.0" ixz="0.0" iyy="0.00001" iyz="0.0" izz="0.0000018"/>
    </inertial>
    <visual>
      <origin rpy="0 0 0" xyz="0 0 0"/>
      <geometry name="rh_rfproximal_visual">
        <mesh filename="avatar_model/shadow_hand/meshes/collision_stl/finger_proximal.stl" scale="0.001 0.001 0.001"/>
      </geometry>
      <material name="Grey"/>
    </visual>
    <collision>
      <origin rpy="0 0 0" xyz="0 0 0.025"/>
      <geometry name="rh_rfproximal_collision_geom">
        <cylinder length="0.040" radius="0.007"/>
      </geometry>
    </collision>
  </link>
  <joint name="rh_RFJ3" type="revolute">
    <parent link="rh_rfknuckle"/>
    <child link="rh_rfproximal"/>
    <origin rpy="0 0 0" xyz="0 0 0"/>
    <axis xyz="1 0 0"/>
    <limit effort="2" lower="-0.2617993877991494" upper="1.5707963267948966" velocity="2.0"/>
    <dynamics damping="0.1"/>
  </joint>
  <gazebo reference="rh_RFJ3">
    <provideFeedback>1</provideFeedback>
    <implicitSpringDamper>1</implicitSpringDamper>
  </gazebo>
  <transmission name="rh_rfproximal_transmission">
    <type>sr_mechanism_model/SimpleTransmission</type>
    <actuator name="rh_RFJ3">
      <mechanicalReduction>1</mechanicalReduction>
    </actuator>
    <joint name="rh_RFJ3">
      <hardwareInterface>EffortJointInterface</hardwareInterface>
      <hardwareInterface>PositionJointInterface</hardwareInterface>
    </joint>
  </transmission>
  <gazebo reference="rh_rfproximal">
    <selfCollide>true</selfCollide>
  </gazebo>
  <link name="rh_rfmiddle">
    <inertial>
      <origin rpy="0 0 0" xyz="0 0 0.0125"/>
      <mass value="0.017"/>
      <inertia ixx="0.0000026" ixy="0.0" ixz="0.0" iyy="0.0000027" iyz="0.0" izz="0.00000087"/>
    </inertial>
    <visual>
      <origin rpy="0 0 0" xyz="0 0 0"/>
      <geometry name="rh_rfmiddle_visual">
        <mesh filename="avatar_model/shadow_hand/meshes/collision_stl/finger_middle.stl" scale="0.001 0.001 0.001"/>
      </geometry>
      <material name="Grey"/>
    </visual>
    <collision>
      <origin rpy="0 0 0" xyz="0 0 0.0125"/>
      <geometry name="rh_rfmiddle_collision_geom">
        <cylinder length="0.025" radius="0.007"/>
      </geometry>
    </collision>
    <collision>
      <origin rpy="0 0 0" xyz="0 0 0.0"/>
      <geometry>
        <sphere radius="0.007"/>
      </geometry>
    </collision>
    <collision>
      <origin rpy="0 0 0" xyz="0 0 0.025"/>
      <geometry>
        <sphere radius="0.007"/>
      </geometry>
    </collision>
  </link>
  <joint name="rh_RFJ2" type="revolute">
    <parent link="rh_rfproximal"/>
    <child link="rh_rfmiddle"/>
    <origin rpy="0 0 0" xyz="0 0 0.045"/>
    <axis xyz="1 0 0"/>
    <limit effort="2" lower="0" upper="1.5707963267948966" velocity="2.0"/>
    <dynamics damping="0.1"/>
  </joint>
  <gazebo reference="rh_RFJ2">
    <provideFeedback>1</provideFeedback>
    <implicitSpringDamper>1</implicitSpringDamper>
  </gazebo>
  <transmission name="rh_rfmiddle_transmission">
    <type>sr_mechanism_model/J0Transmission</type>
    <actuator name="rh_RFJ0">
      <mechanicalReduction>1</mechanicalReduction>
    </actuator>
    <joint name="rh_RFJ1">
      <hardwareInterface>EffortJointInterface</hardwareInterface>
      <hardwareInterface>PositionJointInterface</hardwareInterface>
    </joint>
  </transmission>
  <gazebo reference="rh_rfmiddle">
    <selfCollide>true</selfCollide>
  </gazebo>
  <link name="rh_rfdistal">
    <inertial>
      <mass value="0.012"/>
      <origin xyz="0 0 0.012"/>
      <inertia ixx="0.00000094" ixy="0.0" ixz="0.0" iyy="0.0000011" iyz="0.0" izz="0.00000053"/>
    </inertial>
    <visual>
      <origin rpy="0 0 0" xyz="0 0 0"/>
      <geometry name="rh_rfdistal_visual">
        <mesh filename="avatar_model/shadow_hand/meshes/collision_stl/finger_distal.stl" scale="0.001 0.001 0.001"/>
      </geometry>
    </visual>
    <collision>
      <origin rpy="0 0 0" xyz="0 0 0"/>
      <geometry name="rh_rfdistal_collision_geom">
        <mesh filename="avatar_model/shadow_hand/meshes/collision_stl/finger_distal.stl" scale="0.001 0.001 0.001"/>
      </geometry>
    </collision>
  </link>
  <joint name="rh_RFJ1" type="revolute">
    <parent link="rh_rfmiddle"/>
    <child link="rh_rfdistal"/>
    <origin rpy="0 0 0" xyz="0 0 0.025"/>
    <axis xyz="1 0 0"/>
    <!-- standard distal joint -->
    <limit effort="2" lower="0" upper="1.5707963267948966" velocity="2.0"/>
    <dynamics damping="0.1"/>
  </joint>
  <gazebo reference="rh_RFJ1">
    <provideFeedback>1</provideFeedback>
    <implicitSpringDamper>1</implicitSpringDamper>
  </gazebo>
  <link name="rh_rftip">
    <inertial>
      <mass value="0.001"/>
      <inertia ixx="0.0" ixy="0.0" ixz="0.0" iyy="0.0" iyz="0.0" izz="0.0"/>
    </inertial>
  </link>
  <joint name="rh_RFtip" type="fixed">
    <parent link="rh_rfdistal"/>
    <child link="rh_rftip"/>
    <origin rpy="0 0 0" xyz="0 0 0.026"/>
  </joint>
  <gazebo reference="rh_rfdistal">
    <sensor name="rh_rfdistal_contact" type="contact">
      <always_on>1</always_on>
      <update_rate>1000.0</update_rate>
      <contact>
        <collision>rh_rfdistal_collision</collision>
        <topic>rh_rfdistal_collision</topic>
      </contact>
      <plugin filename="libgazebo_ros_bumper.so" name="rh_rfdistal_gazebo_ros_bumper_controller">
        <alwaysOn>true</alwaysOn>
        <frameName>rh_rfdistal</frameName>
        <updateRate>100.0</updateRate>
        <bumperTopicName>contacts/rh_rf/distal</bumperTopicName>
      </plugin>
    </sensor>
    <mu1 value="500.0"/>
    <mu2 value="500.0"/>
    <kp value="10000000.0"/>
    <kd value="1.0"/>
    <selfCollide>true</selfCollide>
  </gazebo>
  <link name="rh_lfmetacarpal">
    <inertial>
      <origin rpy="0 0.9599 0" xyz="0.03174867647058824 0 0.02235294117647059"/>
      <mass value="0.030"/>
      <inertia ixx="0.0000145" ixy="0.0" ixz="0.0" iyy="0.00001638" iyz="0.0" izz="0.000004272"/>
    </inertial>
    <visual>
      <origin rpy="0 0.9599 0" xyz="0 0 0"/>
      <geometry name="rh_lfmetacarpal_visual">
        <mesh filename="avatar_model/shadow_hand/meshes/collision_stl/metacarpal.stl" scale="0.001 0.001 0.001"/>
      </geometry>
      <material name="Grey"/>
    </visual>
    <collision>
      <origin rpy="0 0.9599 0" xyz="0.026986375 0 0.019"/>
      <geometry name="rh_lfmetacarpal_collision_geom">
        <box size="0.018 0.024 0.040"/>
      </geometry>
    </collision>
  </link>
  <joint name="rh_LFJ5" type="revolute">
    <parent link="rh_palm"/>
    <child link="rh_lfmetacarpal"/>
    <origin rpy="0 -0.9599 0" xyz="-0.033 0 0.02071"/>
    <axis xyz="1 0 0"/>
    <limit effort="2" lower="0" upper="0.7853981633974483" velocity="2.0"/>
    <dynamics damping="0.1"/>
  </joint>
  <gazebo reference="rh_LFJ5">
    <provideFeedback>1</provideFeedback>
    <implicitSpringDamper>1</implicitSpringDamper>
  </gazebo>
  <transmission name="rh_lfmetacarpal_transmission">
    <type>sr_mechanism_model/SimpleTransmission</type>
    <actuator name="rh_LFJ5">
      <mechanicalReduction>1</mechanicalReduction>
    </actuator>
    <joint name="rh_LFJ5">
      <hardwareInterface>EffortJointInterface</hardwareInterface>
      <hardwareInterface>PositionJointInterface</hardwareInterface>
    </joint>
  </transmission>
  <gazebo reference="rh_lfmetacarpal">
    <selfCollide>true</selfCollide>
  </gazebo>
  <link name="rh_lfknuckle">
    <inertial>
      <origin rpy="0 0 0" xyz="0 0 0"/>
      <mass value="0.008"/>
      <inertia ixx="0.00000026" ixy="0.0" ixz="0.0" iyy="0.00000026" iyz="0.0" izz="0.00000032"/>
    </inertial>
    <visual>
      <origin rpy="0 0 0" xyz="0 0 0.0005"/>
      <geometry name="rh_lfknuckle_visual">
        <mesh filename="avatar_model/shadow_hand/meshes/collision_stl/knuckle.stl" scale="0.001 0.001 0.001"/>
      </geometry>
      <material name="LightGrey"/>
    </visual>
    <collision>
      <origin rpy="0 1.5708 0" xyz="0 0 0"/>
      <geometry name="rh_lfknuckle_collision_geom">
        <cylinder length="0.014" radius="0.007"/>
      </geometry>
    </collision>
  </link>
  <joint name="rh_LFJ4" type="revolute">
    <parent link="rh_lfmetacarpal"/>
    <child link="rh_lfknuckle"/>
    <!--<origin xyz="0.033 0 0.095" rpy="0 0 0" />-->
    <origin rpy="0 0.9599 0" xyz="0.05397275 0 0.03779463"/>
    <axis xyz="0 1 0"/>
    <limit effort="2" lower="-0.3490658503988659" upper="0.3490658503988659" velocity="2.0"/>
    <dynamics damping="0.1"/>
  </joint>
  <gazebo reference="rh_LFJ4">
    <provideFeedback>1</provideFeedback>
    <implicitSpringDamper>1</implicitSpringDamper>
  </gazebo>
  <transmission name="rh_lfknuckle_transmission">
    <type>sr_mechanism_model/SimpleTransmission</type>
    <actuator name="rh_LFJ4">
      <mechanicalReduction>1</mechanicalReduction>
    </actuator>
    <joint name="rh_LFJ4">
      <hardwareInterface>EffortJointInterface</hardwareInterface>
      <hardwareInterface>PositionJointInterface</hardwareInterface>
    </joint>
  </transmission>
  <gazebo reference="rh_lfknuckle">
    <!-- knuckle is not highly exposed, so bumper is not useful -->
    <material>Gazebo/Grey</material>
  </gazebo>
  <link name="rh_lfproximal">
    <inertial>
      <mass value="0.030"/>
      <origin xyz="0 0 0.0225"/>
      <inertia ixx="0.0000098" ixy="0.0" ixz="0.0" iyy="0.00001" iyz="0.0" izz="0.0000018"/>
    </inertial>
    <visual>
      <origin rpy="0 0 0" xyz="0 0 0"/>
      <geometry name="rh_lfproximal_visual">
        <mesh filename="avatar_model/shadow_hand/meshes/collision_stl/finger_proximal.stl" scale="0.001 0.001 0.001"/>
      </geometry>
      <material name="Grey"/>
    </visual>
    <collision>
      <origin rpy="0 0 0" xyz="0 0 0.025"/>
      <geometry name="rh_lfproximal_collision_geom">
        <cylinder length="0.040" radius="0.007"/>
      </geometry>
    </collision>
  </link>
  <joint name="rh_LFJ3" type="revolute">
    <parent link="rh_lfknuckle"/>
    <child link="rh_lfproximal"/>
    <origin rpy="0 0 0" xyz="0 0 0"/>
    <axis xyz="1 0 0"/>
    <limit effort="2" lower="-0.2617993877991494" upper="1.5707963267948966" velocity="2.0"/>
    <dynamics damping="0.1"/>
  </joint>
  <gazebo reference="rh_LFJ3">
    <provideFeedback>1</provideFeedback>
    <implicitSpringDamper>1</implicitSpringDamper>
  </gazebo>
  <transmission name="rh_lfproximal_transmission">
    <type>sr_mechanism_model/SimpleTransmission</type>
    <actuator name="rh_LFJ3">
      <mechanicalReduction>1</mechanicalReduction>
    </actuator>
    <joint name="rh_LFJ3">
      <hardwareInterface>EffortJointInterface</hardwareInterface>
      <hardwareInterface>PositionJointInterface</hardwareInterface>
    </joint>
  </transmission>
  <gazebo reference="rh_lfproximal">
    <selfCollide>true</selfCollide>
  </gazebo>
  <link name="rh_lfmiddle">
    <inertial>
      <origin rpy="0 0 0" xyz="0 0 0.0125"/>
      <mass value="0.017"/>
      <inertia ixx="0.0000026" ixy="0.0" ixz="0.0" iyy="0.0000027" iyz="0.0" izz="0.00000087"/>
    </inertial>
    <visual>
      <origin rpy="0 0 0" xyz="0 0 0"/>
      <geometry name="rh_lfmiddle_visual">
        <mesh filename="avatar_model/shadow_hand/meshes/collision_stl/finger_middle.stl" scale="0.001 0.001 0.001"/>
      </geometry>
      <material name="Grey"/>
    </visual>
    <collision>
      <origin rpy="0 0 0" xyz="0 0 0.0125"/>
      <geometry name="rh_lfmiddle_collision_geom">
        <cylinder length="0.025" radius="0.007"/>
      </geometry>
    </collision>
    <collision>
      <origin rpy="0 0 0" xyz="0 0 0.0"/>
      <geometry>
        <sphere radius="0.007"/>
      </geometry>
    </collision>
    <collision>
      <origin rpy="0 0 0" xyz="0 0 0.025"/>
      <geometry>
        <sphere radius="0.007"/>
      </geometry>
    </collision>
  </link>
  <joint name="rh_LFJ2" type="revolute">
    <parent link="rh_lfproximal"/>
    <child link="rh_lfmiddle"/>
    <origin rpy="0 0 0" xyz="0 0 0.045"/>
    <axis xyz="1 0 0"/>
    <limit effort="2" lower="0" upper="1.5707963267948966" velocity="2.0"/>
    <dynamics damping="0.1"/>
  </joint>
  <gazebo reference="rh_LFJ2">
    <provideFeedback>1</provideFeedback>
    <implicitSpringDamper>1</implicitSpringDamper>
  </gazebo>
  <transmission name="rh_lfmiddle_transmission">
    <type>sr_mechanism_model/J0Transmission</type>
    <actuator name="rh_LFJ0">
      <mechanicalReduction>1</mechanicalReduction>
    </actuator>
    <joint name="rh_LFJ1">
      <hardwareInterface>EffortJointInterface</hardwareInterface>
      <hardwareInterface>PositionJointInterface</hardwareInterface>
    </joint>
  </transmission>
  <gazebo reference="rh_lfmiddle">
    <selfCollide>true</selfCollide>
  </gazebo>
  <link name="rh_lfdistal">
    <inertial>
      <mass value="0.012"/>
      <origin xyz="0 0 0.012"/>
      <inertia ixx="0.00000094" ixy="0.0" ixz="0.0" iyy="0.0000011" iyz="0.0" izz="0.00000053"/>
    </inertial>
    <visual>
      <origin rpy="0 0 0" xyz="0 0 0"/>
      <geometry name="rh_lfdistal_visual">
        <mesh filename="avatar_model/shadow_hand/meshes/collision_stl/finger_distal.stl" scale="0.001 0.001 0.001"/>
      </geometry>
    </visual>
    <collision>
      <origin rpy="0 0 0" xyz="0 0 0"/>
      <geometry name="rh_lfdistal_collision_geom">
        <mesh filename="avatar_model/shadow_hand/meshes/collision_stl/finger_distal.stl" scale="0.001 0.001 0.001"/>
      </geometry>
    </collision>
  </link>
  <joint name="rh_LFJ1" type="revolute">
    <parent link="rh_lfmiddle"/>
    <child link="rh_lfdistal"/>
    <origin rpy="0 0 0" xyz="0 0 0.025"/>
    <axis xyz="1 0 0"/>
    <!-- standard distal joint -->
    <limit effort="2" lower="0" upper="1.5707963267948966" velocity="2.0"/>
    <dynamics damping="0.1"/>
  </joint>
  <gazebo reference="rh_LFJ1">
    <provideFeedback>1</provideFeedback>
    <implicitSpringDamper>1</implicitSpringDamper>
  </gazebo>
  <link name="rh_lftip">
    <inertial>
      <mass value="0.001"/>
      <inertia ixx="0.0" ixy="0.0" ixz="0.0" iyy="0.0" iyz="0.0" izz="0.0"/>
    </inertial>
  </link>
  <joint name="rh_LFtip" type="fixed">
    <parent link="rh_lfdistal"/>
    <child link="rh_lftip"/>
    <origin rpy="0 0 0" xyz="0 0 0.026"/>
  </joint>
  <gazebo reference="rh_lfdistal">
    <sensor name="rh_lfdistal_contact" type="contact">
      <always_on>1</always_on>
      <update_rate>1000.0</update_rate>
      <contact>
        <collision>rh_lfdistal_collision</collision>
        <topic>rh_lfdistal_collision</topic>
      </contact>
      <plugin filename="libgazebo_ros_bumper.so" name="rh_lfdistal_gazebo_ros_bumper_controller">
        <alwaysOn>true</alwaysOn>
        <frameName>rh_lfdistal</frameName>
        <updateRate>100.0</updateRate>
        <bumperTopicName>contacts/rh_lf/distal</bumperTopicName>
      </plugin>
    </sensor>
    <mu1 value="500.0"/>
    <mu2 value="500.0"/>
    <kp value="10000000.0"/>
    <kd value="1.0"/>
    <selfCollide>true</selfCollide>
  </gazebo>
  <link name="rh_thbase">
    <inertial>
      <mass value="0.010"/>
      <origin rpy="0 0 0" xyz="0 0 0"/>
      <inertia ixx="0.00000016" ixy="0.0" ixz="0.0" iyy="0.00000016" iyz="0.0" izz="0.00000016"/>
    </inertial>
    <visual>
      <origin rpy="0 0 0" xyz="0 0 0"/>
      <geometry name="rh_thbase_visual">
        <box size="0.001 0.001 0.001"/>
      </geometry>
      <material name="shadow_thbase_material">
        <color rgba="0.5 0.5 0.5 1.0"/>
      </material>
    </visual>
    <collision>
      <origin rpy="0 0 0" xyz="0 0 0"/>
      <geometry name="rh_thbase_collision_geom">
        <sphere radius="0.011"/>
      </geometry>
    </collision>
  </link>
  <joint name="rh_THJ5" type="revolute">
    <parent link="rh_palm"/>
    <child link="rh_thbase"/>
    <origin rpy="-0.7853981633974483 0 -1.5707963267948966" xyz="0.034 -0.00858 0.029"/>
    <axis xyz="0 0 -1"/>
    <limit effort="5.0" lower="-1.0471975511965976" upper="1.0471975511965976" velocity="4.0"/>
    <dynamics damping="0.2"/>
  </joint>
  <gazebo reference="rh_THJ5">
    <provideFeedback>1</provideFeedback>
    <implicitSpringDamper>1</implicitSpringDamper>
  </gazebo>
  <transmission name="rh_thbase_transmission">
    <type>sr_mechanism_model/SimpleTransmission</type>
    <actuator name="rh_THJ5">
      <mechanicalReduction>1</mechanicalReduction>
    </actuator>
    <joint name="rh_THJ5">
      <hardwareInterface>EffortJointInterface</hardwareInterface>
      <hardwareInterface>PositionJointInterface</hardwareInterface>
    </joint>
  </transmission>
  <gazebo reference="rh_thbase">
    <!-- base is inside the proximal and not exposed, so bumper is not needed -->
    <selfCollide>false</selfCollide>
  </gazebo>
  <link name="rh_thproximal">
    <inertial>
      <mass value="0.040"/>
      <origin rpy="0 0 0" xyz="0 0 0.019"/>
      <inertia ixx="0.0000136" ixy="0.0" ixz="0.0" iyy="0.0000136" iyz="0.0" izz="0.00000313"/>
    </inertial>
    <visual>
      <origin rpy="0 0 1.5707963267948966" xyz="0 0 0"/>
      <geometry name="rh_thproximal_visual">
        <mesh filename="avatar_model/shadow_hand/meshes/collision_stl/thumb_proximal.stl" scale="0.001 0.001 0.001"/>
      </geometry>
      <material name="shadow_thproximal_material">
        <color rgba="0.2 0.2 0.2 1.0"/>
      </material>
    </visual>
    <collision>
      <origin rpy="0 0 0" xyz="0 0 0.020"/>
      <geometry name="rh_thproximal_collision_geom">
        <cylinder length="0.018" radius="0.012"/>
      </geometry>
    </collision>
  </link>
  <joint name="rh_THJ4" type="revolute">
    <parent link="rh_thbase"/>
    <child link="rh_thproximal"/>
    <origin rpy="0 0 0" xyz="0 0 0"/>
    <axis xyz="0 1 0"/>
    <limit effort="3" lower="0.0" upper="1.2217304763960306" velocity="4.0"/>
    <dynamics damping="0.2"/>
  </joint>
  <gazebo reference="rh_THJ4">
    <provideFeedback>1</provideFeedback>
    <implicitSpringDamper>1</implicitSpringDamper>
  </gazebo>
  <transmission name="rh_thproximal_transmission">
    <type>sr_mechanism_model/SimpleTransmission</type>
    <actuator name="rh_THJ4">
      <mechanicalReduction>1</mechanicalReduction>
    </actuator>
    <joint name="rh_THJ4">
      <hardwareInterface>EffortJointInterface</hardwareInterface>
      <hardwareInterface>PositionJointInterface</hardwareInterface>
    </joint>
  </transmission>
  <gazebo reference="rh_thproximal">
    <selfCollide>false</selfCollide>
  </gazebo>
  <link name="rh_thhub">
    <inertial>
      <mass value="0.005"/>
      <origin rpy="0 0 0" xyz="0 0 0"/>
      <inertia ixx="0.000001" ixy="0.0" ixz="0.0" iyy="0.000001" iyz="0.0" izz="0.0000003"/>
    </inertial>
    <visual>
      <origin rpy="0 0 0" xyz="0 0 0"/>
      <geometry name="rh_thhub_visual">
        <box size="0.001 0.001 0.001"/>
      </geometry>
      <material name="shadow_thhub_material">
        <color rgba="0.7 0.7 0.7 1.0"/>
      </material>
    </visual>
    <collision>
      <origin rpy="0 0 0" xyz="0 0 0"/>
      <geometry name="rh_thhub_collision_geom">
        <sphere radius="0.010"/>
      </geometry>
    </collision>
  </link>
  <joint name="rh_THJ3" type="revolute">
    <parent link="rh_thproximal"/>
    <child link="rh_thhub"/>
    <origin rpy="0 0 0" xyz="0 0 0.038"/>
    <axis xyz="0 1 0"/>
    <limit effort="2.0" lower="-0.20943951023931953" upper="0.20943951023931953" velocity="4.0"/>
    <dynamics damping="0.2"/>
  </joint>
  <gazebo reference="rh_THJ3">
    <provideFeedback>1</provideFeedback>
    <implicitSpringDamper>1</implicitSpringDamper>
  </gazebo>
  <transmission name="rh_thhub_transmission">
    <type>sr_mechanism_model/SimpleTransmission</type>
    <actuator name="rh_THJ3">
      <mechanicalReduction>1</mechanicalReduction>
    </actuator>
    <joint name="rh_THJ3">
      <hardwareInterface>EffortJointInterface</hardwareInterface>
      <hardwareInterface>PositionJointInterface</hardwareInterface>
    </joint>
  </transmission>
  <gazebo reference="rh_thhub">
    <!-- hub is inside the proximal and not exposed, so bumper is not needed -->
    <selfCollide>false</selfCollide>
  </gazebo>
  <link name="rh_thmiddle">
    <inertial>
      <mass value="0.020"/>
      <origin rpy="0 0 0" xyz="0 0 0.016"/>
      <inertia ixx="0.0000051" ixy="0.0" ixz="0.0" iyy="0.0000051" iyz="0.0" izz="0.00000121"/>
    </inertial>
    <visual>
      <origin rpy="0 0 1.5707963267948966" xyz="0 0 0"/>
      <geometry name="rh_thmiddle_visual">
        <mesh filename="avatar_model/shadow_hand/meshes/collision_stl/thumb_middle.stl" scale="0.001 0.001 0.001"/>
      </geometry>
      <material name="shadow_thmiddle_material">
        <color rgba="0.2 0.2 0.2 1.0"/>
      </material>
    </visual>
    <collision>
      <origin rpy="0 0 0" xyz="0 0 0.012"/>
      <geometry name="rh_thmiddle_collision_geom">
        <cylinder length="0.018" radius="0.011"/>
      </geometry>
    </collision>
    <collision>
      <origin rpy="0 0 0" xyz="0 0 0.019"/>
      <geometry>
        <sphere radius="0.011"/>
      </geometry>
    </collision>
    <collision>
      <origin rpy="0 1.5708 0" xyz="0 0 0.032"/>
      <geometry>
        <cylinder length="0.014" radius="0.010"/>
      </geometry>
    </collision>
  </link>
  <joint name="rh_THJ2" type="revolute">
    <parent link="rh_thhub"/>
    <child link="rh_thmiddle"/>
    <origin rpy="0 0 0" xyz="0 0 0"/>
    <axis xyz="1 0 0"/>
    <limit effort="2.0" lower="-0.6981317007977318" upper="0.6981317007977318" velocity="2.0"/>
    <dynamics damping="0.1"/>
  </joint>
  <gazebo reference="rh_THJ2">
    <provideFeedback>1</provideFeedback>
    <implicitSpringDamper>1</implicitSpringDamper>
  </gazebo>
  <transmission name="rh_thmiddle_transmission">
    <type>sr_mechanism_model/SimpleTransmission</type>
    <actuator name="rh_THJ2">
      <mechanicalReduction>1</mechanicalReduction>
    </actuator>
    <joint name="rh_THJ2">
      <hardwareInterface>EffortJointInterface</hardwareInterface>
      <hardwareInterface>PositionJointInterface</hardwareInterface>
    </joint>
  </transmission>
  <gazebo reference="rh_thmiddle">
  </gazebo>
  <!-- common -->
  <link name="rh_thdistal">
    <inertial>
      <mass value="0.016"/>
      <origin rpy="0 0 0" xyz="0 0 0.01375"/>
      <inertia ixx="0.0000021" ixy="0.0" ixz="0.0" iyy="0.0000022" iyz="0.0" izz="0.000001"/>
    </inertial>
    <visual>
      <origin rpy="0 0 0" xyz="0 0 0"/>
      <geometry name="rh_thdistal_visual">
        <mesh filename="avatar_model/shadow_hand/meshes/collision_stl/thumb_distal.stl" scale="0.001 0.001 0.001"/>
      </geometry>
      <material name="shadow_thmiddle_material">
        <color rgba="0.2 0.2 0.2 1.0"/>
      </material>
    </visual>
    <collision>
      <origin rpy="0 0 0" xyz="0 0 0"/>
      <geometry name="rh_thmiddle_collision_geom">
        <mesh filename="avatar_model/shadow_hand/meshes/collision_stl/thumb_distal.stl" scale="0.001 0.001 0.001"/>
      </geometry>
    </collision>
  </link>
  <joint name="rh_THJ1" type="revolute">
    <parent link="rh_thmiddle"/>
    <child link="rh_thdistal"/>
    <origin rpy="0 0 0" xyz="0 0 0.032"/>
    <axis xyz="1 0 0"/>
    <limit effort="1.0" lower="-0.2617993877991494" upper="1.5707963267948966" velocity="4.0"/>
    <dynamics damping="0.2"/>
  </joint>
  <gazebo reference="rh_THJ1">
    <provideFeedback>1</provideFeedback>
    <implicitSpringDamper>1</implicitSpringDamper>
  </gazebo>
  <link name="rh_thtip">
    <inertial>
      <mass value="0.001"/>
      <inertia ixx="0.0" ixy="0.0" ixz="0.0" iyy="0.0" iyz="0.0" izz="0.0"/>
    </inertial>
  </link>
  <joint name="rh_thtip" type="fixed">
    <parent link="rh_thdistal"/>
    <child link="rh_thtip"/>
    <origin rpy="0 0 0" xyz="0 0 0.0275"/>
  </joint>
  <gazebo reference="rh_thdistal">
    <sensor name="rh_thdistal_contact" type="contact">
      <always_on>1</always_on>
      <update_rate>1000.0</update_rate>
      <contact>
        <collision>rh_thdistal_collision</collision>
        <topic>rh_thdistal_collision</topic>
      </contact>
      <plugin filename="libgazebo_ros_bumper.so" name="rh_thdistal_gazebo_ros_bumper_controller">
        <alwaysOn>true</alwaysOn>
        <frameName>rh_thdistal</frameName>
        <updateRate>100.0</updateRate>
        <bumperTopicName>contacts/rh_th/distal</bumperTopicName>
      </plugin>
    </sensor>
    <mu1 value="500.0"/>
    <mu2 value="500.0"/>
    <kp value="10000000.0"/>
    <kd value="1.0"/>
    <selfCollide>true</selfCollide>
  </gazebo>
  <transmission name="rh_thdistal_transmission">
    <type>sr_mechanism_model/SimpleTransmission</type>
    <actuator name="rh_THJ1">
      <mechanicalReduction>1</mechanicalReduction>
    </actuator>
    <joint name="rh_THJ1">
      <hardwareInterface>EffortJointInterface</hardwareInterface>
      <hardwareInterface>PositionJointInterface</hardwareInterface>
    </joint>
  </transmission>
  <!-- Gofa 1 Workspace (this should look towards the working space, centered on Gofa 1) -->
  <link name="gofa1_workspace"/>
  <joint name="gofa1_base_workspace_joint" type="fixed">
    <parent link="gofa1_workspace"/>
    <child link="gofa1_base_link"/>
    <origin rpy="0.0 -0.523599 0.0" xyz="0.0 0.0 0.095"/>
  </joint>
  <!-- Gofa 2 Workspace (this should look towards the working space, centered on Gofa 2) -->
  <link name="gofa2_workspace"/>
  <joint name="gofa2_workspace" type="fixed">
    <parent link="gofa2_workspace"/>
    <child link="gofa2_base_link"/>
    <origin rpy="0.0 -0.523599 3.14" xyz="0.0 0.0 0.095"/>
  </joint>
  <!-- Distance between arms & rotation -->
  <joint name="gofa_dist" type="fixed">
    <parent link="gofa1_workspace"/>
    <child link="gofa2_workspace"/>
    <origin rpy="0.0 0.0 0.0" xyz="0.5687 0.0 0.0"/>
  </joint>
  <!-- Distance to Avatar middle assembly -->
  <link name="gofas_midpoint"/>
  <joint name="gofas_midpoint" type="fixed">
    <parent link="gofa1_workspace"/>
    <child link="gofas_midpoint"/>
    <origin rpy="0.0 0.0 0.0" xyz="0.3175 0.0 0.0"/>
  </joint>
  <material name="xarm6_Black">
    <color rgba="0.0 0.0 0.0 1.0"/>
  </material>
  <material name="xarm6_Red">
    <color rgba="0.8 0.0 0.0 1.0"/>
  </material>
  <material name="xarm6_White">
    <color rgba="1.0 1.0 1.0 1.0"/>
  </material>
  <material name="xarm6_Silver">
    <color rgba="0.753 0.753 0.753 1.0"/>
  </material>
  <link name="xarm6_link_base">
    <inertial>
      <origin rpy="0 0 0" xyz="0.0 0.0 0.09103"/>
      <mass value="2.7"/>
      <inertia ixx="0.00494875" ixy="-3.5E-06" ixz="1.25E-05" iyy="0.00494174" iyz="1.67E-06" izz="0.002219"/>
    </inertial>
    <visual>
      <geometry>
        <mesh filename="avatar_model/xarm/visual_stl/base.stl"/>
      </geometry>
      <origin rpy="0 0 0" xyz="0 0 0"/>
      <material name="xarm6_White"/>
    </visual>
    <collision>
      <geometry>
        <mesh filename="avatar_model/xarm/visual_stl/base.stl"/>
      </geometry>
      <origin rpy="0 0 0" xyz="0 0 0"/>
    </collision>
  </link>
  <link name="xarm6_link1">
    <visual>
      <geometry>
        <mesh filename="avatar_model/xarm/visual_stl/link1.stl"/>
      </geometry>
      <origin rpy="0 0 0" xyz="0 0 0"/>
      <material name="xarm6_White"/>
    </visual>
    <collision>
      <geometry>
        <mesh filename="avatar_model/xarm/visual_stl/link1.stl"/>
      </geometry>
      <origin rpy="0 0 0" xyz="0 0 0"/>
    </collision>
  </link>
  <joint name="xarm6_joint1" type="revolute">
    <parent link="xarm6_link_base"/>
    <child link="xarm6_link1"/>
    <origin rpy="0 0 0" xyz="0 0 0.267"/>
    <axis xyz="0 0 1"/>
    <limit effort="50.0" lower="-6.283185307179586" upper="6.283185307179586" velocity="3.14"/>
    <dynamics damping="1.0" friction="1.0"/>
  </joint>
  <link name="xarm6_link2">
    <visual>
      <geometry>
        <mesh filename="avatar_model/xarm/visual_stl/link2.stl"/>
      </geometry>
      <origin rpy="0 0 0" xyz="0 0 0"/>
      <material name="xarm6_White"/>
    </visual>
    <collision>
      <geometry>
        <mesh filename="avatar_model/xarm/visual_stl/link2.stl"/>
      </geometry>
      <origin rpy="0 0 0" xyz="0 0 0"/>
    </collision>
  </link>
  <joint name="xarm6_joint2" type="revolute">
    <parent link="xarm6_link1"/>
    <child link="xarm6_link2"/>
    <origin rpy="-1.5708 0 0" xyz="0 0 0"/>
    <axis xyz="0 0 1"/>
    <limit effort="50.0" lower="-2.059" upper="2.0944" velocity="3.14"/>
    <dynamics damping="1.0" friction="1.0"/>
  </joint>
  <link name="xarm6_link3">
    <visual>
      <geometry>
        <mesh filename="avatar_model/xarm/visual_stl/link3.stl"/>
      </geometry>
      <origin rpy="0 0 0" xyz="0 0 0"/>
      <material name="xarm6_White"/>
    </visual>
    <collision>
      <geometry>
        <mesh filename="avatar_model/xarm/visual_stl/link3.stl"/>
      </geometry>
      <origin rpy="0 0 0" xyz="0 0 0"/>
    </collision>
  </link>
  <joint name="xarm6_joint3" type="revolute">
    <parent link="xarm6_link2"/>
    <child link="xarm6_link3"/>
    <origin rpy="0 0 0" xyz="0.0535 -0.2845 0"/>
    <axis xyz="0 0 1"/>
    <limit effort="32.0" lower="-3.927" upper="0.19198" velocity="3.14"/>
    <dynamics damping="1.0" friction="1.0"/>
  </joint>
  <link name="xarm6_link4">
    <visual>
      <geometry>
        <mesh filename="avatar_model/xarm/visual_stl/link4.stl"/>
      </geometry>
      <origin rpy="0 0 0" xyz="0 0 0"/>
      <material name="xarm6_White"/>
    </visual>
    <collision>
      <geometry>
        <mesh filename="avatar_model/xarm/visual_stl/link4.stl"/>
      </geometry>
      <origin rpy="0 0 0" xyz="0 0 0"/>
    </collision>
  </link>
  <joint name="xarm6_joint4" type="revolute">
    <parent link="xarm6_link3"/>
    <child link="xarm6_link4"/>
    <origin rpy="-1.5708 0 0" xyz="0.0775 0.3425 0"/>
    <axis xyz="0 0 1"/>
    <limit effort="32.0" lower="-6.283185307179586" upper="6.283185307179586" velocity="3.14"/>
    <dynamics damping="1.0" friction="1.0"/>
  </joint>
  <link name="xarm6_link5">
    <visual>
      <geometry>
        <mesh filename="avatar_model/xarm/visual_stl/link5.stl"/>
      </geometry>
      <origin rpy="0 0 0" xyz="0 0 0"/>
      <material name="xarm6_White"/>
    </visual>
    <collision>
      <geometry>
        <mesh filename="avatar_model/xarm/visual_stl/link5.stl"/>
      </geometry>
      <origin rpy="0 0 0" xyz="0 0 0"/>
    </collision>
  </link>
  <joint name="xarm6_joint5" type="revolute">
    <parent link="xarm6_link4"/>
    <child link="xarm6_link5"/>
    <origin rpy="1.5708 0 0" xyz="0 0 0"/>
    <axis xyz="0 0 1"/>
    <limit effort="32.0" lower="-1.69297" upper="3.141592653589793" velocity="3.14"/>
    <dynamics damping="1.0" friction="1.0"/>
  </joint>
  <link name="xarm6_link6">
    <visual>
      <geometry>
        <mesh filename="avatar_model/xarm/visual_stl/link6.stl"/>
      </geometry>
      <origin rpy="0 0 0" xyz="0 0 0"/>
      <material name="xarm6_Silver"/>
    </visual>
    <collision>
      <geometry>
        <mesh filename="avatar_model/xarm/end_tool/collision/end_tool.stl"/>
      </geometry>
      <origin rpy="0 0 0" xyz="0 0 0"/>
    </collision>
  </link>
  <joint name="xarm6_joint6" type="revolute">
    <parent link="xarm6_link5"/>
    <child link="xarm6_link6"/>
    <origin rpy="-1.5708 0 0" xyz="0.076 0.097 0"/>
    <axis xyz="0 0 1"/>
    <limit effort="20.0" lower="-6.283185307179586" upper="6.283185307179586" velocity="3.14"/>
    <dynamics damping="1.0" friction="1.0"/>
  </joint>
  <!-- <link name="${prefix}link_eef" />
    <joint name="${prefix}joint_eef" type="fixed">
      <origin xyz="0 0 0" rpy="0 0 0" />
      <parent link="${prefix}link6" />
      <child link="${prefix}link_eef" />
    </joint> -->
  <!-- Neck Cam Assm Link - bbox -->
  <link name="neck_cam_assm_mount">
    <visual>
      <origin rpy="0 0 0" xyz="0 0 -0.065"/>
      <geometry>
        <box size="0.055 0.12 0.15"/>
      </geometry>
    </visual>
    <collision>
      <origin rpy="0 0 0" xyz="0 0 -0.065"/>
      <geometry>
        <box size="0.055 0.12 0.155"/>
      </geometry>
    </collision>
  </link>
  <joint name="neck_cam_assm_mount" type="fixed">
    <parent link="xarm6_link6"/>
    <child link="neck_cam_assm_mount"/>
    <origin rpy="1.57 -1.57 0.0" xyz="0.0 -0.1067 0.0225"/>
    <!-- -0.1067 physically measured with calipers from xarm ee center to fish-eye lens -->
  </joint>
  <!-- Neck Cam - consistent with hmd_reconciled means z-forward, x-down, y-left-->
  <link name="neck_cam_assm"/>
  <joint name="neck_cam_assm" type="fixed">
    <parent link="neck_cam_assm_mount"/>
    <child link="neck_cam_assm"/>
    <origin rpy="0 0 3.14" xyz="0.0 0.0 0.0"/>
  </joint>
  <link name="neck_cam_left_eye"/>
  <joint name="neck_cam_left_eye" type="fixed">
    <parent link="neck_cam_assm"/>
    <child link="neck_cam_left_eye"/>
    <origin rpy="0 0 0" xyz="0.0 0.034 0.0"/>
  </joint>
  <link name="neck_cam_right_eye"/>
  <joint name="neck_cam_right_eye" type="fixed">
    <parent link="neck_cam_assm"/>
    <child link="neck_cam_right_eye"/>
    <origin rpy="0 0 0" xyz="0.0 -0.034 0.0"/>
  </joint>
  <!-- Neck workspace -->
  <link name="xarm6_workspace"/>
  <joint name="xarm6_workspace" type="fixed">
    <parent link="xarm6_workspace"/>
    <child link="xarm6_link_base"/>
    <origin rpy="0.0 0.0 1.517" xyz="0.0 0.0 0.0"/>
  </joint>
  <!-- Neck w.r.t. Gofa1  (measured as 12") -->
  <joint name="neck_dist" type="fixed">
    <parent link="gofa1_workspace"/>
    <child link="xarm6_workspace"/>
    <origin rpy="0.0 0.0 0.0" xyz="0.264 0.3683 0.0"/>
  </joint>
  <!-- Center of Avatar task workspace -->
  <link name="avatar_task_ws"/>
  <joint name="avatar_task_ws" type="fixed">
    <parent link="xarm6_workspace"/>
    <child link="avatar_task_ws"/>
    <origin rpy="0.0 0.0 0.0" xyz="0.0 0.6 0.0"/>
  </joint>
  <ros2_control name="FakeSystem" type="system">
    <hardware>
      <!-- By default, set up controllers for simulation. This won't work on real hardware -->
      <plugin>mock_components/GenericSystem</plugin>
    </hardware>
    <joint name="gofa1_joint_1">
      <command_interface name="position"/>
      <state_interface name="position">
        <param name="initial_value">0</param>
      </state_interface>
      <state_interface name="velocity"/>
    </joint>
    <joint name="gofa1_joint_2">
      <command_interface name="position"/>
      <state_interface name="position">
        <param name="initial_value">0</param>
      </state_interface>
      <state_interface name="velocity"/>
    </joint>
    <joint name="gofa1_joint_3">
      <command_interface name="position"/>
      <state_interface name="position">
        <param name="initial_value">0</param>
      </state_interface>
      <state_interface name="velocity"/>
    </joint>
    <joint name="gofa1_joint_4">
      <command_interface name="position"/>
      <state_interface name="position">
        <param name="initial_value">0</param>
      </state_interface>
      <state_interface name="velocity"/>
    </joint>
    <joint name="gofa1_joint_5">
      <command_interface name="position"/>
      <state_interface name="position">
        <param name="initial_value">0</param>
      </state_interface>
      <state_interface name="velocity"/>
    </joint>
    <joint name="gofa1_joint_6">
      <command_interface name="position"/>
      <state_interface name="position">
        <param name="initial_value">0</param>
      </state_interface>
      <state_interface name="velocity"/>
    </joint>
    <joint name="lh_WRJ2">
      <command_interface name="position"/>
      <state_interface name="position">
        <param name="initial_value">0</param>
      </state_interface>
      <state_interface name="velocity"/>
    </joint>
    <joint name="lh_WRJ1">
      <command_interface name="position"/>
      <state_interface name="position">
        <param name="initial_value">0</param>
      </state_interface>
      <state_interface name="velocity"/>
    </joint>
    <joint name="gofa2_joint_1">
      <command_interface name="position"/>
      <state_interface name="position">
        <param name="initial_value">0</param>
      </state_interface>
      <state_interface name="velocity"/>
    </joint>
    <joint name="gofa2_joint_2">
      <command_interface name="position"/>
      <state_interface name="position">
        <param name="initial_value">0</param>
      </state_interface>
      <state_interface name="velocity"/>
    </joint>
    <joint name="gofa2_joint_3">
      <command_interface name="position"/>
      <state_interface name="position">
        <param name="initial_value">0</param>
      </state_interface>
      <state_interface name="velocity"/>
    </joint>
    <joint name="gofa2_joint_4">
      <command_interface name="position"/>
      <state_interface name="position">
        <param name="initial_value">0</param>
      </state_interface>
      <state_interface name="velocity"/>
    </joint>
    <joint name="gofa2_joint_5">
      <command_interface name="position"/>
      <state_interface name="position">
        <param name="initial_value">0</param>
      </state_interface>
      <state_interface name="velocity"/>
    </joint>
    <joint name="gofa2_joint_6">
      <command_interface name="position"/>
      <state_interface name="position">
        <param name="initial_value">0</param>
      </state_interface>
      <state_interface name="velocity"/>
    </joint>
    <joint name="rh_WRJ2">
      <command_interface name="position"/>
      <state_interface name="position">
        <param name="initial_value">0</param>
      </state_interface>
      <state_interface name="velocity"/>
    </joint>
    <joint name="rh_WRJ1">
      <command_interface name="position"/>
      <state_interface name="position">
        <param name="initial_value">0</param>
      </state_interface>
      <state_interface name="velocity"/>
    </joint>
    <joint name="xarm6_joint1">
      <command_interface name="position"/>
      <state_interface name="position">
        <param name="initial_value">0</param>
      </state_interface>
      <state_interface name="velocity"/>
    </joint>
    <joint name="xarm6_joint2">
      <command_interface name="position"/>
      <state_interface name="position">
        <param name="initial_value">0</param>
      </state_interface>
      <state_interface name="velocity"/>
    </joint>
    <joint name="xarm6_joint3">
      <command_interface name="position"/>
      <state_interface name="position">
        <param name="initial_value">0</param>
      </state_interface>
      <state_interface name="velocity"/>
    </joint>
    <joint name="xarm6_joint4">
      <command_interface name="position"/>
      <state_interface name="position">
        <param name="initial_value">0</param>
      </state_interface>
      <state_interface name="velocity"/>
    </joint>
    <joint name="xarm6_joint5">
      <command_interface name="position"/>
      <state_interface name="position">
        <param name="initial_value">0</param>
      </state_interface>
      <state_interface name="velocity"/>
    </joint>
    <joint name="xarm6_joint6">
      <command_interface name="position"/>
      <state_interface name="position">
        <param name="initial_value">0</param>
      </state_interface>
      <state_interface name="velocity"/>
    </joint>
  </ros2_control>
</robot>
